Workbook

Sheet 읽어보기
A1: 숲속 원정대 — 장비 DB (1단계)
A3: 규칙 (요청 사양)
B4: 등급 8단계: UC < C < R < SR < SSR < UR < Legend(L) < Elder(E).
B5: 부위: 직업별 무기 · 갑옷 · 소울 메달 / 공통 반지 · 목걸이 · 벨트.
B6: 직업 무기·갑옷은 직업에 맞는 주 스탯 + 고유 스킬 효과가 붙는다. 추가 옵션은 R부터 1개씩 늘어 UR에서 최대 4개.
B7: L: 보석 슬롯 1개 + (직업 특성 스탯 또는 스킬 보너스) 0~1개.
B8: E: 보석 슬롯 1~3개 + 직업 특성 스탯 1개 + 스킬 보너스 0~2개.
B9: 보석: 각 스테이지 보스 처치 보상. 등급별 효과 개수 R까지 1개 · UR까지 2개 · E까지 3개.
A10: 밸런스 원칙 (전략 RPG)
B11: 큰 적은 [방어 태세](받는 피해 감소)와 [그로기 게이지]를 가진다. 기절·스킬·차지 끊기로 게이지를 깎으면 6초간 무방비(방어 해제 + 받는 피해 +50%).
B12: → 비슷한 등급에서는 딜만 올려 밀어붙이는 플레이(딜찍누)보다 기믹 공략이 확실히 유리하도록 조정. 딜만으로 이기려면 2등급 이상 차이가 필요하도록 목표.
B13: → 추가 옵션/보석에 공략 스탯(그로기 피해, 그로기 적 피해, 기절·도발 지속)을 넣어 장비로도 공략 빌드를 만들 수 있게 함.
B14: → 순수 딜 옵션은 1줄당 전투력 약 1.1%, 생존/공략 옵션은 약 1.5%로 책정 (딜 옵션이 더 약함).
A15: 시트 안내
B16: 등급 · 스탯 · 장비_기본 · 추가옵션 · 직업특성스탯 · 스킬보너스 · 보석 · 난이도 · 드랍테이블: 원본 데이터 (파란 글씨 = 수정 가능한 입력값).
B17: 장비_등급별: 장비 49종 × 8등급의 실제 수치. 모두 수식(장비_기본 × 등급 배율) — 입력값을 바꾸면 자동 갱신.
B18: 밸런스분석: 등급별 전투력, 옵션 공정성, 누적 상한, 전투 시뮬 승률(기믹 공략 vs 딜만), 딜찍누 지수. 시뮬 결과는 tools/equip_balance.cjs 실행 결과 값.
A19: 색 규칙
B20: 파란 글씨 = 입력값 / 검정 = 수식 / 초록 = 다른 시트 참조 / 노란 칸 = 핵심 가정.
A21: 가정 · 확인이 필요한 점
B22: 1) 등급 순서는 요청에 적힌 순서대로 UC를 최하위로 두었다 (일반적으로는 C < UC인 경우도 있음).
B23: 2) L·E도 추가 옵션 4개를 유지 (UR 최대 4개 규칙의 연장). L·E의 차별점은 보석 슬롯 · 특성 스탯 · 스킬 보너스.
B24: 3) 공통 장신구(반지·목걸이·벨트)의 L·E 직업 특성 스탯/스킬 보너스는 착용한 캐릭터의 직업 기준으로 붙는다.
B25: 4) 소울 메달 = 직업 특성 스탯 + ①(갑옷)·②(무기) 스킬 위력 강화. 필살기 변형은 캐릭터 중복 돌파로 이동. 메달의 최종 역할은 docs/GAME_DESIGN.md 8장에 보류 안으로 기록.
B26: 5) 장비가 원정 사이에 유지(영구 성장)된다고 가정 → 적 강함을 8단계 난이도로 나눔 (난이도 시트). 데모의 기본 던전 = 견습(T1) 아래 단계.
B27: 6) "각 스테이지 보스" — 현재 데모는 5스테이지 보스 1종뿐. 보석 드랍은 보스 노드 기준으로 정의 (스테이지별 중간 보스 추가 시 동일 테이블 사용).
B28: 7) 승률 수치는 헤드리스 시뮬(3개 파티 조합 × 시드, 4스테이지 일반/정예 + 보스) 기준이며 실제 플레이어 실력에 따라 달라진다.

Sheet 등급
A1: 등급
A2: 주 스탯 배율 · 옵션 개수 · 옵션 배율 · 고유 효과 배율 · 보석 슬롯 · 특성/스킬 보너스 · 보석 등급 효과
A4: 등급 | B4: 이름 | C4: 주 스탯 배율 | D4: 추가 옵션 수 | E4: 옵션 수치 배율 | F4: 고유 효과 배율 | G4: 보석 슬롯 최소 | H4: 보석 슬롯 최대 | I4: 특성 스탯 최소 | J4: 특성 스탯 최대 | K4: 스킬 보너스 최소 | L4: 스킬 보너스 최대 | M4: 보석 효과 개수 | N4: 보석 수치 배율 | O4: 주 스탯 증가율(전 등급 대비)
A5: UC | B5: UC | C5: 1 | D5: 0 | E5: 0 | F5: 1 | G5: 0 | H5: 0 | I5: 0 | J5: 0 | K5: 0 | L5: 0 | M5: 1 | N5: 1 | O5: =IF(ROW()=5,"-",C5/C4-1) -> -
A6: C | B6: C | C6: 1.45 | D6: 0 | E6: 0 | F6: 1.35 | G6: 0 | H6: 0 | I6: 0 | J6: 0 | K6: 0 | L6: 0 | M6: 1 | N6: 1.25 | O6: =IF(ROW()=5,"-",C6/C5-1) -> 0.45
A7: R | B7: R | C7: 1.7 | D7: 1 | E7: 1 | F7: 1.5 | G7: 0 | H7: 0 | I7: 0 | J7: 0 | K7: 0 | L7: 0 | M7: 1 | N7: 1.5 | O7: =IF(ROW()=5,"-",C7/C6-1) -> 0.17241379
A8: SR | B8: SR | C8: 2.1 | D8: 2 | E8: 1.15 | F8: 1.75 | G8: 0 | H8: 0 | I8: 0 | J8: 0 | K8: 0 | L8: 0 | M8: 2 | N8: 1.8 | O8: =IF(ROW()=5,"-",C8/C7-1) -> 0.23529412
A9: SSR | B9: SSR | C9: 2.55 | D9: 3 | E9: 1.3 | F9: 2 | G9: 0 | H9: 0 | I9: 0 | J9: 0 | K9: 0 | L9: 0 | M9: 2 | N9: 2.1 | O9: =IF(ROW()=5,"-",C9/C8-1) -> 0.21428571
A10: UR | B10: UR | C10: 3.05 | D10: 4 | E10: 1.5 | F10: 2.3 | G10: 0 | H10: 0 | I10: 0 | J10: 0 | K10: 0 | L10: 0 | M10: 2 | N10: 2.4 | O10: =IF(ROW()=5,"-",C10/C9-1) -> 0.19607843
A11: L | B11: Legend | C11: 3.2 | D11: 4 | E11: 1.55 | F11: 2.65 | G11: 1 | H11: 1 | I11: 0 | J11: 1 | K11: 0 | L11: 1 | M11: 3 | N11: 2.65 | O11: =IF(ROW()=5,"-",C11/C10-1) -> 0.049180328
A12: E | B12: Elder | C12: 3.3 | D12: 4 | E12: 1.58 | F12: 3 | G12: 1 | H12: 3 | I12: 1 | J12: 1 | K12: 0 | L12: 2 | M12: 3 | N12: 2.9 | O12: =IF(ROW()=5,"-",C12/C11-1) -> 0.03125
A14: L 추가 효과 확률
A15: 없음 | B15: 30 | C15: =B15/SUM($B$15:$B$17) -> 0.3
A16: 특성 스탯 | B16: 35 | C16: =B16/SUM($B$15:$B$17) -> 0.35
A17: 스킬 보너스 | B17: 35 | C17: =B17/SUM($B$15:$B$17) -> 0.35
A19: E 보석 슬롯 확률
A20: 1칸 | B20: 55 | C20: =B20/SUM($B$20:$B$22) -> 0.55
A21: 2칸 | B21: 33 | C21: =B21/SUM($B$20:$B$22) -> 0.33
A22: 3칸 | B22: 12 | C22: =B22/SUM($B$20:$B$22) -> 0.12
A24: E 스킬 보너스 확률
A25: 0개 | B25: 40 | C25: =B25/SUM($B$25:$B$27) -> 0.4
A26: 1개 | B26: 45 | C26: =B26/SUM($B$25:$B$27) -> 0.45
A27: 2개 | B27: 15 | C27: =B27/SUM($B$25:$B$27) -> 0.15
A29: 가중치는 상대값. 확률 = 가중치 ÷ 합계.

Sheet 스탯
A1: 스탯
A2: 전투력 가중치(pw): 스탯 1%p가 전투력 몇 %에 해당하는지 (밸런스 분석용 근사)
A4: 키 | B4: 이름 | C4: 단위 | D4: 전투력 가중치 | E4: 상한 | F4: 공략 스탯 | G4: 비고
A5: atk | B5: 공격력 | C5: 수치 | D5: 환산 | E5: - | G5: 직업 기본 공격력 대비로 환산
A6: hp | B6: 체력 | C6: 수치 | D6: 환산 | E6: - | G6: 직업 기본 체력 대비로 환산
A7: atk_pct | B7: 공격력% | C7: % | D7: 0.5 | E7: -
A8: hp_pct | B8: 체력% | C8: % | D8: 0.5 | E8: -
A9: dr | B9: 받는 피해 감소 | C9: % | D9: 0.6 | E9: 0.5
A10: aspd | B10: 공격 속도 | C10: % | D10: 0.3 | E10: 0.5
A11: crit | B11: 치명타 확률 | C11: % | D11: 0.3 | E11: 0.6
A12: critdmg | B12: 치명타 피해 | C12: % | D12: 0.1 | E12: -
A13: skilldmg | B13: 스킬 피해 | C13: % | D13: 0.2 | E13: -
A14: cdr | B14: 쿨타임 감소 | C14: % | D14: 0.35 | E14: 0.4
A15: heal | B15: 회복량 | C15: % | D15: 0.2 | E15: -
A16: ultgain | B16: 필살기 충전 | C16: % | D16: 0.12 | E16: 0.8
A17: mspd | B17: 이동 속도 | C17: % | D17: 0.08 | E17: 0.5
A18: dotdmg | B18: 지속 피해 | C18: % | D18: 0.06 | E18: -
A19: ccdur | B19: 기절·도발 지속 | C19: % | D19: 0.1 | E19: - | F19: O
A20: breakdmg | B20: 그로기 피해 | C20: % | D20: 0.1 | E20: - | F20: O | G20: 그로기 게이지를 더 크게 깎는다 (공략 스탯)
A21: s1pow | B21: ① 스킬 위력 | C21: % | D21: 0.12 | E21: - | G21: 소울 메달 주 스탯 (갑옷 스킬)
A22: s2pow | B22: ② 스킬 위력 | C22: % | D22: 0.12 | E22: - | G22: 소울 메달 주 스탯 (무기 스킬)
A23: vsbroken | B23: 그로기 적 피해 | C23: % | D23: 0.1 | E23: - | F23: O | G23: 그로기 상태 적에게 주는 피해 (공략 스탯)

Sheet 장비_기본
A1: 장비 기본값 (UC 기준)
A2: 등급별 수치 = 기본값 × 등급 배율. 공격력·체력은 수치, 나머지는 비율.
A4: ID | B4: 이름 | C4: 부위 | D4: 직업 | E4: 라인 | F4: 주 스탯1 | G4: 기본값1 | H4: 주 스탯2 | I4: 기본값2 | J4: 고유 효과 | K4: 고유 기본값 | L4: 단위 | M4: 고유 효과 키
A5: tank_weapon_1 | B5: 수호자의 메이스 | C5: 무기 | D5: 탱커 | E5: 1 | F5: 공격력 | G5: 2.2 | H5: 받는 피해 감소 | I5: 0.006 | J5: ② 방패 강타 그로기 피해 +[값]% | K5: 15 | L5: % | M5: s2_break
A6: tank_weapon_2 | B6: 맹세의 장검 | C6: 무기 | D6: 탱커 | E6: 2 | F6: 공격력 | G6: 2.2 | H6: 받는 피해 감소 | I6: 0.006 | J6: ① 도발 중 받는 피해 감소 +[값]%p | K6: 3 | L6: %p | M6: s1_guard
A7: tank_weapon_3 | B7: 성채의 철퇴 | C7: 무기 | D7: 탱커 | E7: 3 | F7: 공격력 | G7: 2.2 | H7: 받는 피해 감소 | I7: 0.006 | J7: 평타 적중 시 [값]% 확률로 0.6초 기절 | K7: 3 | L7: % | M7: basic_stun_chance
A8: tank_armor_1 | B8: 성벽 판금갑 | C8: 갑옷 | D8: 탱커 | E8: 1 | F8: 체력 | G8: 52 | H8: 받는 피해 감소 | I8: 0.006 | J8: 차지 공격 피해 -[값]% | K8: 6 | L8: % | M8: charge_dr
A9: tank_armor_2 | B9: 맹세의 사슬갑 | C9: 갑옷 | D9: 탱커 | E9: 2 | F9: 체력 | G9: 52 | H9: 받는 피해 감소 | I9: 0.006 | J9: ① 도발 지속 +[값]초 | K9: 0.3 | L9: 초 | M9: s1_taunt_dur
A10: tank_armor_3 | B10: 가시 갑옷 | C10: 갑옷 | D10: 탱커 | E10: 3 | F10: 체력 | G10: 52 | H10: 받는 피해 감소 | I10: 0.006 | J10: 받은 근접 피해의 [값]% 반사 | K10: 5 | L10: % | M10: thorns
A11: tank_medal_1 | B11: 불굴의 소울 메달 | C11: 소울 메달 | D11: 탱커 | E11: 1 | F11: 받는 피해 감소 | G11: 0.012 | H11: ① 스킬 위력 | I11: 0.1 | J11: -
A12: tank_medal_2 | B12: 수호성의 소울 메달 | C12: 소울 메달 | D12: 탱커 | E12: 2 | F12: 받는 피해 감소 | G12: 0.012 | H12: ② 스킬 위력 | I12: 0.1 | J12: -
A13: melee_weapon_1 | B13: 바람의 쌍검 | C13: 무기 | D13: 근딜 | E13: 1 | F13: 공격력 | G13: 4 | H13: 치명타 피해 | I13: 0.03 | J13: ① 급소 베기 출혈 피해 +[값]% | K13: 10 | L13: % | M13: s1_bleed
A14: melee_weapon_2 | B14: 파쇄자의 대검 | C14: 무기 | D14: 근딜 | E14: 2 | F14: 공격력 | G14: 4 | H14: 치명타 피해 | I14: 0.03 | J14: 그로기 적에게 피해 +[값]% | K14: 8 | L14: % | M14: vs_broken
A15: melee_weapon_3 | B15: 그림자 단검 | C15: 무기 | D15: 근딜 | E15: 3 | F15: 공격력 | G15: 4 | H15: 치명타 피해 | I15: 0.03 | J15: ② 회전 베기 범위 +[값]% | K15: 5 | L15: % | M15: s2_area
A16: melee_armor_1 | B16: 사냥꾼의 가죽갑 | C16: 갑옷 | D16: 근딜 | E16: 1 | F16: 체력 | G16: 30 | H16: 공격 속도 | I16: 0.02 | J16: 적 처치 시 2초간 공격 속도 +[값]% | K16: 10 | L16: % | M16: kill_aspd
A17: melee_armor_2 | B17: 검무사의 경갑 | C17: 갑옷 | D17: 근딜 | E17: 2 | F17: 체력 | G17: 30 | H17: 공격 속도 | I17: 0.02 | J17: ② 회전 베기 쿨타임 -[값]% | K17: 4 | L17: % | M17: s2_cd
A18: melee_armor_3 | B18: 핏빛 망토 | C18: 갑옷 | D18: 근딜 | E18: 3 | F18: 체력 | G18: 30 | H18: 공격 속도 | I18: 0.02 | J18: 출혈 걸린 적에게 피해 +[값]% | K18: 5 | L18: % | M18: vs_bleed
A19: melee_medal_1 | B19: 검귀의 소울 메달 | C19: 소울 메달 | D19: 근딜 | E19: 1 | F19: 치명타 피해 | G19: 0.06 | H19: ① 스킬 위력 | I19: 0.1 | J19: -
A20: melee_medal_2 | B20: 투지의 소울 메달 | C20: 소울 메달 | D20: 근딜 | E20: 2 | F20: 치명타 피해 | G20: 0.06 | H20: ② 스킬 위력 | I20: 0.1 | J20: -
A21: ranged_weapon_1 | B21: 매의 장궁 | C21: 무기 | D21: 원딜 | E21: 1 | F21: 공격력 | G21: 3.6 | H21: 치명타 확률 | I21: 0.008 | J21: ① 관통 사격 취약 지속 +[값]초 | K21: 0.5 | L21: 초 | M21: s1_vuln_dur
A22: ranged_weapon_2 | B22: 폭풍의 연궁 | C22: 무기 | D22: 원딜 | E22: 2 | F22: 공격력 | G22: 3.6 | H22: 치명타 확률 | I22: 0.008 | J22: 평타 [값]% 확률로 2연사 | K22: 6 | L22: % | M22: double_shot
A23: ranged_weapon_3 | B23: 은빛 석궁 | C23: 무기 | D23: 원딜 | E23: 3 | F23: 공격력 | G23: 3.6 | H23: 치명타 확률 | I23: 0.008 | J23: ③ 집중 사격 위력 +[값]% | K23: 8 | L23: % | M23: ult_power
A24: ranged_armor_1 | B24: 숲지기 가죽갑 | C24: 갑옷 | D24: 원딜 | E24: 1 | F24: 체력 | G24: 26 | H24: 이동 속도 | I24: 0.025 | J24: ② 화살비 범위 +[값]% | K24: 5 | L24: % | M24: s2_area
A25: ranged_armor_2 | B25: 그림자 망토 | C25: 갑옷 | D25: 원딜 | E25: 2 | F25: 체력 | G25: 26 | H25: 이동 속도 | I25: 0.025 | J25: 적이 70px 안에 있으면 받는 피해 -[값]% | K25: 6 | L25: % | M25: near_dr
A26: ranged_armor_3 | B26: 추적자의 조끼 | C26: 갑옷 | D26: 원딜 | E26: 3 | F26: 체력 | G26: 26 | H26: 이동 속도 | I26: 0.025 | J26: 차지·호출을 끊으면 필살기 게이지 +[값] | K26: 6 | M26: counter_ult
A27: ranged_medal_1 | B27: 명사수의 소울 메달 | C27: 소울 메달 | D27: 원딜 | E27: 1 | F27: 치명타 확률 | G27: 0.016 | H27: ① 스킬 위력 | I27: 0.1 | J27: -
A28: ranged_medal_2 | B28: 바람의 소울 메달 | C28: 소울 메달 | D28: 원딜 | E28: 2 | F28: 치명타 확률 | G28: 0.016 | H28: ② 스킬 위력 | I28: 0.1 | J28: -
A29: mage_weapon_1 | B29: 별빛 지팡이 | C29: 무기 | D29: 매지션 | E29: 1 | F29: 공격력 | G29: 4.4 | H29: 스킬 피해 | I29: 0.02 | J29: ① 별빛 탄 화상 피해 +[값]% | K29: 10 | L29: % | M29: s1_burn
A30: mage_weapon_2 | B30: 유성의 홀 | C30: 무기 | D30: 매지션 | E30: 2 | F30: 공격력 | G30: 4.4 | H30: 스킬 피해 | I30: 0.02 | J30: ② 유성우 범위 +[값]% | K30: 6 | L30: % | M30: s2_area
A31: mage_weapon_3 | B31: 금단의 마도서 | C31: 무기 | D31: 매지션 | E31: 3 | F31: 공격력 | G31: 4.4 | H31: 스킬 피해 | I31: 0.02 | J31: ③ 대마법이 그로기 적에게 위력 +[값]% | K31: 12 | L31: % | M31: ult_vs_broken
A32: mage_armor_1 | B32: 현자의 로브 | C32: 갑옷 | D32: 매지션 | E32: 1 | F32: 체력 | G32: 24 | H32: 쿨타임 감소 | I32: 0.01 | J32: 쿨타임 감소 +[값]% | K32: 1.5 | L32: % | M32: cdr_extra
A33: mage_armor_2 | B33: 불꽃 망토 | C33: 갑옷 | D33: 매지션 | E33: 2 | F33: 체력 | G33: 24 | H33: 쿨타임 감소 | I33: 0.01 | J33: 화상 지속 +[값]초 | K33: 0.4 | L33: 초 | M33: burn_dur
A34: mage_armor_3 | B34: 마력 장막 로브 | C34: 갑옷 | D34: 매지션 | E34: 3 | F34: 체력 | G34: 24 | H34: 쿨타임 감소 | I34: 0.01 | J34: 전투 시작 시 최대 HP [값]% 보호막 | K34: 6 | L34: % | M34: start_shield
A35: mage_medal_1 | B35: 대마도사의 소울 메달 | C35: 소울 메달 | D35: 매지션 | E35: 1 | F35: 스킬 피해 | G35: 0.04 | H35: ① 스킬 위력 | I35: 0.1 | J35: -
A36: mage_medal_2 | B36: 별의 소울 메달 | C36: 소울 메달 | D36: 매지션 | E36: 2 | F36: 스킬 피해 | G36: 0.04 | H36: ② 스킬 위력 | I36: 0.1 | J36: -
A37: support_weapon_1 | B37: 생명의 지팡이 | C37: 무기 | D37: 서포터 | E37: 1 | F37: 공격력 | G37: 1.6 | H37: 회복량 | I37: 0.025 | J37: ① 치유 회복량 +[값]% | K37: 8 | L37: % | M37: s1_heal
A38: support_weapon_2 | B38: 빛의 홀 | C38: 무기 | D38: 서포터 | E38: 2 | F38: 공격력 | G38: 1.6 | H38: 회복량 | I38: 0.025 | J38: ② 광역 치유 범위 +[값]% | K38: 6 | L38: % | M38: s2_area
A39: support_weapon_3 | B39: 정화의 성구 | C39: 무기 | D39: 서포터 | E39: 3 | F39: 공격력 | G39: 1.6 | H39: 회복량 | I39: 0.025 | J39: 치유받은 아군 3초간 받는 피해 -[값]% | K39: 5 | L39: % | M39: heal_dr
A40: support_armor_1 | B40: 순백의 사제복 | C40: 갑옷 | D40: 서포터 | E40: 1 | F40: 체력 | G40: 28 | H40: 필살기 충전 | I40: 0.025 | J40: 파티 회복 받는 양 +[값]% | K40: 3 | L40: % | M40: party_healrecv
A41: support_armor_2 | B41: 수호의 성의 | C41: 갑옷 | D41: 서포터 | E41: 2 | F41: 체력 | G41: 28 | H41: 필살기 충전 | I41: 0.025 | J41: ③ 생명의 나무 지속 +[값]초 | K41: 0.5 | L41: 초 | M41: ult_dur
...

Sheet 장비_등급별
A1: 장비 × 등급 수치 (수식)
A2: 주 스탯 = 기본값 × 주 스탯 배율 / 고유 효과 = 고유 기본값 × 고유 효과 배율. 옵션·보석 슬롯은 등급 시트 참조.
A4: 이름 | B4: 부위 | C4: 직업 | D4: 등급 | E4: 주 스탯1 | F4: 값1 | G4: 주 스탯2 | H4: 값2 | I4: 고유 효과 | J4: 고유 값 | K4: 추가 옵션 수 | L4: 보석 슬롯 | M4: 특성 스탯 | N4: 스킬 보너스
A5: =장비_기본!B5 -> 수호자의 메이스 | B5: =장비_기본!C5 -> 무기 | C5: =장비_기본!D5 -> 탱커 | D5: UC | E5: =장비_기본!F5 -> 공격력 | F5: =장비_기본!G5*INDEX(등급!$C$5:$C$12,MATCH($D5,등급!$A$5:$A$12,0)) -> 2.2 | G5: =장비_기본!H5 -> 받는 피해 감소 | H5: =장비_기본!I5*INDEX(등급!$C$5:$C$12,MATCH($D5,등급!$A$5:$A$12,0)) -> 0.006 | I5: =장비_기본!J5 -> ② 방패 강타 그로기 피해 +[값]% | J5: =ROUND(장비_기본!K5*INDEX(등급!$F$5:$F$12,MATCH($D5,등급!$A$5:$A$12,0)),1) -> 15 | K5: =INDEX(등급!$D$5:$D$12,MATCH($D5,등급!$A$5:$A$12,0)) -> 0 | L5: =IF(INDEX(등급!$H$5:$H$12,MATCH($D5,등급!$A$5:$A$12,0))=0,"-",IF(INDEX(등급!$G$5:$G$12,MATCH($D5,등급!$A$5:$A$12,0))=INDEX(등급!$H$5:$H$12,MATCH($D5,등급!$A$5:$A$12,0)),INDEX(등급!$G$5:$G$12,MATCH($D5,등급!$A$5:$A$12,0))&"칸",INDEX(등급!$G$5:$G$12,MATCH($D5,등급!$A$5:$A$12,0))&"~"&INDEX(등급!$H$5:$H$12,MATCH($D5,등급!$A$5:$A$12,0))&"칸")) -> - | M5: =IF(INDEX(등급!$J$5:$J$12,MATCH($D5,등급!$A$5:$A$12,0))=0,"-",IF(INDEX(등급!$I$5:$I$12,MATCH($D5,등급!$A$5:$A$12,0))=INDEX(등급!$J$5:$J$12,MATCH($D5,등급!$A$5:$A$12,0)),INDEX(등급!$I$5:$I$12,MATCH($D5,등급!$A$5:$A$12,0))&"개",INDEX(등급!$I$5:$I$12,MATCH($D5,등급!$A$5:$A$12,0))&"~"&INDEX(등급!$J$5:$J$12,MATCH($D5,등급!$A$5:$A$12,0))&"개")) -> - | N5: =IF(INDEX(등급!$L$5:$L$12,MATCH($D5,등급!$A$5:$A$12,0))=0,"-",INDEX(등급!$K$5:$K$12,MATCH($D5,등급!$A$5:$A$12,0))&"~"&INDEX(등급!$L$5:$L$12,MATCH($D5,등급!$A$5:$A$12,0))&"개") -> -
A6: =장비_기본!B5 -> 수호자의 메이스 | B6: =장비_기본!C5 -> 무기 | C6: =장비_기본!D5 -> 탱커 | D6: C | E6: =장비_기본!F5 -> 공격력 | F6: =장비_기본!G5*INDEX(등급!$C$5:$C$12,MATCH($D6,등급!$A$5:$A$12,0)) -> 3.19 | G6: =장비_기본!H5 -> 받는 피해 감소 | H6: =장비_기본!I5*INDEX(등급!$C$5:$C$12,MATCH($D6,등급!$A$5:$A$12,0)) -> 0.0087 | I6: =장비_기본!J5 -> ② 방패 강타 그로기 피해 +[값]% | J6: =ROUND(장비_기본!K5*INDEX(등급!$F$5:$F$12,MATCH($D6,등급!$A$5:$A$12,0)),1) -> 20.3 | K6: =INDEX(등급!$D$5:$D$12,MATCH($D6,등급!$A$5:$A$12,0)) -> 0 | L6: =IF(INDEX(등급!$H$5:$H$12,MATCH($D6,등급!$A$5:$A$12,0))=0,"-",IF(INDEX(등급!$G$5:$G$12,MATCH($D6,등급!$A$5:$A$12,0))=INDEX(등급!$H$5:$H$12,MATCH($D6,등급!$A$5:$A$12,0)),INDEX(등급!$G$5:$G$12,MATCH($D6,등급!$A$5:$A$12,0))&"칸",INDEX(등급!$G$5:$G$12,MATCH($D6,등급!$A$5:$A$12,0))&"~"&INDEX(등급!$H$5:$H$12,MATCH($D6,등급!$A$5:$A$12,0))&"칸")) -> - | M6: =IF(INDEX(등급!$J$5:$J$12,MATCH($D6,등급!$A$5:$A$12,0))=0,"-",IF(INDEX(등급!$I$5:$I$12,MATCH($D6,등급!$A$5:$A$12,0))=INDEX(등급!$J$5:$J$12,MATCH($D6,등급!$A$5:$A$12,0)),INDEX(등급!$I$5:$I$12,MATCH($D6,등급!$A$5:$A$12,0))&"개",INDEX(등급!$I$5:$I$12,MATCH($D6,등급!$A$5:$A$12,0))&"~"&INDEX(등급!$J$5:$J$12,MATCH($D6,등급!$A$5:$A$12,0))&"개")) -> - | N6: =IF(INDEX(등급!$L$5:$L$12,MATCH($D6,등급!$A$5:$A$12,0))=0,"-",INDEX(등급!$K$5:$K$12,MATCH($D6,등급!$A$5:$A$12,0))&"~"&INDEX(등급!$L$5:$L$12,MATCH($D6,등급!$A$5:$A$12,0))&"개") -> -
A7: =장비_기본!B5 -> 수호자의 메이스 | B7: =장비_기본!C5 -> 무기 | C7: =장비_기본!D5 -> 탱커 | D7: R | E7: =장비_기본!F5 -> 공격력 | F7: =장비_기본!G5*INDEX(등급!$C$5:$C$12,MATCH($D7,등급!$A$5:$A$12,0)) -> 3.74 | G7: =장비_기본!H5 -> 받는 피해 감소 | H7: =장비_기본!I5*INDEX(등급!$C$5:$C$12,MATCH($D7,등급!$A$5:$A$12,0)) -> 0.0102 | I7: =장비_기본!J5 -> ② 방패 강타 그로기 피해 +[값]% | J7: =ROUND(장비_기본!K5*INDEX(등급!$F$5:$F$12,MATCH($D7,등급!$A$5:$A$12,0)),1) -> 22.5 | K7: =INDEX(등급!$D$5:$D$12,MATCH($D7,등급!$A$5:$A$12,0)) -> 1 | L7: =IF(INDEX(등급!$H$5:$H$12,MATCH($D7,등급!$A$5:$A$12,0))=0,"-",IF(INDEX(등급!$G$5:$G$12,MATCH($D7,등급!$A$5:$A$12,0))=INDEX(등급!$H$5:$H$12,MATCH($D7,등급!$A$5:$A$12,0)),INDEX(등급!$G$5:$G$12,MATCH($D7,등급!$A$5:$A$12,0))&"칸",INDEX(등급!$G$5:$G$12,MATCH($D7,등급!$A$5:$A$12,0))&"~"&INDEX(등급!$H$5:$H$12,MATCH($D7,등급!$A$5:$A$12,0))&"칸")) -> - | M7: =IF(INDEX(등급!$J$5:$J$12,MATCH($D7,등급!$A$5:$A$12,0))=0,"-",IF(INDEX(등급!$I$5:$I$12,MATCH($D7,등급!$A$5:$A$12,0))=INDEX(등급!$J$5:$J$12,MATCH($D7,등급!$A$5:$A$12,0)),INDEX(등급!$I$5:$I$12,MATCH($D7,등급!$A$5:$A$12,0))&"개",INDEX(등급!$I$5:$I$12,MATCH($D7,등급!$A$5:$A$12,0))&"~"&INDEX(등급!$J$5:$J$12,MATCH($D7,등급!$A$5:$A$12,0))&"개")) -> - | N7: =IF(INDEX(등급!$L$5:$L$12,MATCH($D7,등급!$A$5:$A$12,0))=0,"-",INDEX(등급!$K$5:$K$12,MATCH($D7,등급!$A$5:$A$12,0))&"~"&INDEX(등급!$L$5:$L$12,MATCH($D7,등급!$A$5:$A$12,0))&"개") -> -
A8: =장비_기본!B5 -> 수호자의 메이스 | B8: =장비_기본!C5 -> 무기 | C8: =장비_기본!D5 -> 탱커 | D8: SR | E8: =장비_기본!F5 -> 공격력 | F8: =장비_기본!G5*INDEX(등급!$C$5:$C$12,MATCH($D8,등급!$A$5:$A$12,0)) -> 4.62 | G8: =장비_기본!H5 -> 받는 피해 감소 | H8: =장비_기본!I5*INDEX(등급!$C$5:$C$12,MATCH($D8,등급!$A$5:$A$12,0)) -> 0.0126 | I8: =장비_기본!J5 -> ② 방패 강타 그로기 피해 +[값]% | J8: =ROUND(장비_기본!K5*INDEX(등급!$F$5:$F$12,MATCH($D8,등급!$A$5:$A$12,0)),1) -> 26.3 | K8: =INDEX(등급!$D$5:$D$12,MATCH($D8,등급!$A$5:$A$12,0)) -> 2 | L8: =IF(INDEX(등급!$H$5:$H$12,MATCH($D8,등급!$A$5:$A$12,0))=0,"-",IF(INDEX(등급!$G$5:$G$12,MATCH($D8,등급!$A$5:$A$12,0))=INDEX(등급!$H$5:$H$12,MATCH($D8,등급!$A$5:$A$12,0)),INDEX(등급!$G$5:$G$12,MATCH($D8,등급!$A$5:$A$12,0))&"칸",INDEX(등급!$G$5:$G$12,MATCH($D8,등급!$A$5:$A$12,0))&"~"&INDEX(등급!$H$5:$H$12,MATCH($D8,등급!$A$5:$A$12,0))&"칸")) -> - | M8: =IF(INDEX(등급!$J$5:$J$12,MATCH($D8,등급!$A$5:$A$12,0))=0,"-",IF(INDEX(등급!$I$5:$I$12,MATCH($D8,등급!$A$5:$A$12,0))=INDEX(등급!$J$5:$J$12,MATCH($D8,등급!$A$5:$A$12,0)),INDEX(등급!$I$5:$I$12,MATCH($D8,등급!$A$5:$A$12,0))&"개",INDEX(등급!$I$5:$I$12,MATCH($D8,등급!$A$5:$A$12,0))&"~"&INDEX(등급!$J$5:$J$12,MATCH($D8,등급!$A$5:$A$12,0))&"개")) -> - | N8: =IF(INDEX(등급!$L$5:$L$12,MATCH($D8,등급!$A$5:$A$12,0))=0,"-",INDEX(등급!$K$5:$K$12,MATCH($D8,등급!$A$5:$A$12,0))&"~"&INDEX(등급!$L$5:$L$12,MATCH($D8,등급!$A$5:$A$12,0))&"개") -> -
A9: =장비_기본!B5 -> 수호자의 메이스 | B9: =장비_기본!C5 -> 무기 | C9: =장비_기본!D5 -> 탱커 | D9: SSR | E9: =장비_기본!F5 -> 공격력 | F9: =장비_기본!G5*INDEX(등급!$C$5:$C$12,MATCH($D9,등급!$A$5:$A$12,0)) -> 5.61 | G9: =장비_기본!H5 -> 받는 피해 감소 | H9: =장비_기본!I5*INDEX(등급!$C$5:$C$12,MATCH($D9,등급!$A$5:$A$12,0)) -> 0.0153 | I9: =장비_기본!J5 -> ② 방패 강타 그로기 피해 +[값]% | J9: =ROUND(장비_기본!K5*INDEX(등급!$F$5:$F$12,MATCH($D9,등급!$A$5:$A$12,0)),1) -> 30 | K9: =INDEX(등급!$D$5:$D$12,MATCH($D9,등급!$A$5:$A$12,0)) -> 3 | L9: =IF(INDEX(등급!$H$5:$H$12,MATCH($D9,등급!$A$5:$A$12,0))=0,"-",IF(INDEX(등급!$G$5:$G$12,MATCH($D9,등급!$A$5:$A$12,0))=INDEX(등급!$H$5:$H$12,MATCH($D9,등급!$A$5:$A$12,0)),INDEX(등급!$G$5:$G$12,MATCH($D9,등급!$A$5:$A$12,0))&"칸",INDEX(등급!$G$5:$G$12,MATCH($D9,등급!$A$5:$A$12,0))&"~"&INDEX(등급!$H$5:$H$12,MATCH($D9,등급!$A$5:$A$12,0))&"칸")) -> - | M9: =IF(INDEX(등급!$J$5:$J$12,MATCH($D9,등급!$A$5:$A$12,0))=0,"-",IF(INDEX(등급!$I$5:$I$12,MATCH($D9,등급!$A$5:$A$12,0))=INDEX(등급!$J$5:$J$12,MATCH($D9,등급!$A$5:$A$12,0)),INDEX(등급!$I$5:$I$12,MATCH($D9,등급!$A$5:$A$12,0))&"개",INDEX(등급!$I$5:$I$12,MATCH($D9,등급!$A$5:$A$12,0))&"~"&INDEX(등급!$J$5:$J$12,MATCH($D9,등급!$A$5:$A$12,0))&"개")) -> - | N9: =IF(INDEX(등급!$L$5:$L$12,MATCH($D9,등급!$A$5:$A$12,0))=0,"-",INDEX(등급!$K$5:$K$12,MATCH($D9,등급!$A$5:$A$12,0))&"~"&INDEX(등급!$L$5:$L$12,MATCH($D9,등급!$A$5:$A$12,0))&"개") -> -
A10: =장비_기본!B5 -> 수호자의 메이스 | B10: =장비_기본!C5 -> 무기 | C10: =장비_기본!D5 -> 탱커 | D10: UR | E10: =장비_기본!F5 -> 공격력 | F10: =장비_기본!G5*INDEX(등급!$C$5:$C$12,MATCH($D10,등급!$A$5:$A$12,0)) -> 6.71 | G10: =장비_기본!H5 -> 받는 피해 감소 | H10: =장비_기본!I5*INDEX(등급!$C$5:$C$12,MATCH($D10,등급!$A$5:$A$12,0)) -> 0.0183 | I10: =장비_기본!J5 -> ② 방패 강타 그로기 피해 +[값]% | J10: =ROUND(장비_기본!K5*INDEX(등급!$F$5:$F$12,MATCH($D10,등급!$A$5:$A$12,0)),1) -> 34.5 | K10: =INDEX(등급!$D$5:$D$12,MATCH($D10,등급!$A$5:$A$12,0)) -> 4 | L10: =IF(INDEX(등급!$H$5:$H$12,MATCH($D10,등급!$A$5:$A$12,0))=0,"-",IF(INDEX(등급!$G$5:$G$12,MATCH($D10,등급!$A$5:$A$12,0))=INDEX(등급!$H$5:$H$12,MATCH($D10,등급!$A$5:$A$12,0)),INDEX(등급!$G$5:$G$12,MATCH($D10,등급!$A$5:$A$12,0))&"칸",INDEX(등급!$G$5:$G$12,MATCH($D10,등급!$A$5:$A$12,0))&"~"&INDEX(등급!$H$5:$H$12,MATCH($D10,등급!$A$5:$A$12,0))&"칸")) -> - | M10: =IF(INDEX(등급!$J$5:$J$12,MATCH($D10,등급!$A$5:$A$12,0))=0,"-",IF(INDEX(등급!$I$5:$I$12,MATCH($D10,등급!$A$5:$A$12,0))=INDEX(등급!$J$5:$J$12,MATCH($D10,등급!$A$5:$A$12,0)),INDEX(등급!$I$5:$I$12,MATCH($D10,등급!$A$5:$A$12,0))&"개",INDEX(등급!$I$5:$I$12,MATCH($D10,등급!$A$5:$A$12,0))&"~"&INDEX(등급!$J$5:$J$12,MATCH($D10,등급!$A$5:$A$12,0))&"개")) -> - | N10: =IF(INDEX(등급!$L$5:$L$12,MATCH($D10,등급!$A$5:$A$12,0))=0,"-",INDEX(등급!$K$5:$K$12,MATCH($D10,등급!$A$5:$A$12,0))&"~"&INDEX(등급!$L$5:$L$12,MATCH($D10,등급!$A$5:$A$12,0))&"개") -> -
A11: =장비_기본!B5 -> 수호자의 메이스 | B11: =장비_기본!C5 -> 무기 | C11: =장비_기본!D5 -> 탱커 | D11: L | E11: =장비_기본!F5 -> 공격력 | F11: =장비_기본!G5*INDEX(등급!$C$5:$C$12,MATCH($D11,등급!$A$5:$A$12,0)) -> 7.04 | G11: =장비_기본!H5 -> 받는 피해 감소 | H11: =장비_기본!I5*INDEX(등급!$C$5:$C$12,MATCH($D11,등급!$A$5:$A$12,0)) -> 0.0192 | I11: =장비_기본!J5 -> ② 방패 강타 그로기 피해 +[값]% | J11: =ROUND(장비_기본!K5*INDEX(등급!$F$5:$F$12,MATCH($D11,등급!$A$5:$A$12,0)),1) -> 39.8 | K11: =INDEX(등급!$D$5:$D$12,MATCH($D11,등급!$A$5:$A$12,0)) -> 4 | L11: =IF(INDEX(등급!$H$5:$H$12,MATCH($D11,등급!$A$5:$A$12,0))=0,"-",IF(INDEX(등급!$G$5:$G$12,MATCH($D11,등급!$A$5:$A$12,0))=INDEX(등급!$H$5:$H$12,MATCH($D11,등급!$A$5:$A$12,0)),INDEX(등급!$G$5:$G$12,MATCH($D11,등급!$A$5:$A$12,0))&"칸",INDEX(등급!$G$5:$G$12,MATCH($D11,등급!$A$5:$A$12,0))&"~"&INDEX(등급!$H$5:$H$12,MATCH($D11,등급!$A$5:$A$12,0))&"칸")) -> 1칸 | M11: =IF(INDEX(등급!$J$5:$J$12,MATCH($D11,등급!$A$5:$A$12,0))=0,"-",IF(INDEX(등급!$I$5:$I$12,MATCH($D11,등급!$A$5:$A$12,0))=INDEX(등급!$J$5:$J$12,MATCH($D11,등급!$A$5:$A$12,0)),INDEX(등급!$I$5:$I$12,MATCH($D11,등급!$A$5:$A$12,0))&"개",INDEX(등급!$I$5:$I$12,MATCH($D11,등급!$A$5:$A$12,0))&"~"&INDEX(등급!$J$5:$J$12,MATCH($D11,등급!$A$5:$A$12,0))&"개")) -> 0~1개 | N11: =IF(INDEX(등급!$L$5:$L$12,MATCH($D11,등급!$A$5:$A$12,0))=0,"-",INDEX(등급!$K$5:$K$12,MATCH($D11,등급!$A$5:$A$12,0))&"~"&INDEX(등급!$L$5:$L$12,MATCH($D11,등급!$A$5:$A$12,0))&"개") -> 0~1개
A12: =장비_기본!B5 -> 수호자의 메이스 | B12: =장비_기본!C5 -> 무기 | C12: =장비_기본!D5 -> 탱커 | D12: E | E12: =장비_기본!F5 -> 공격력 | F12: =장비_기본!G5*INDEX(등급!$C$5:$C$12,MATCH($D12,등급!$A$5:$A$12,0)) -> 7.26 | G12: =장비_기본!H5 -> 받는 피해 감소 | H12: =장비_기본!I5*INDEX(등급!$C$5:$C$12,MATCH($D12,등급!$A$5:$A$12,0)) -> 0.0198 | I12: =장비_기본!J5 -> ② 방패 강타 그로기 피해 +[값]% | J12: =ROUND(장비_기본!K5*INDEX(등급!$F$5:$F$12,MATCH($D12,등급!$A$5:$A$12,0)),1) -> 45 | K12: =INDEX(등급!$D$5:$D$12,MATCH($D12,등급!$A$5:$A$12,0)) -> 4 | L12: =IF(INDEX(등급!$H$5:$H$12,MATCH($D12,등급!$A$5:$A$12,0))=0,"-",IF(INDEX(등급!$G$5:$G$12,MATCH($D12,등급!$A$5:$A$12,0))=INDEX(등급!$H$5:$H$12,MATCH($D12,등급!$A$5:$A$12,0)),INDEX(등급!$G$5:$G$12,MATCH($D12,등급!$A$5:$A$12,0))&"칸",INDEX(등급!$G$5:$G$12,MATCH($D12,등급!$A$5:$A$12,0))&"~"&INDEX(등급!$H$5:$H$12,MATCH($D12,등급!$A$5:$A$12,0))&"칸")) -> 1~3칸 | M12: =IF(INDEX(등급!$J$5:$J$12,MATCH($D12,등급!$A$5:$A$12,0))=0,"-",IF(INDEX(등급!$I$5:$I$12,MATCH($D12,등급!$A$5:$A$12,0))=INDEX(등급!$J$5:$J$12,MATCH($D12,등급!$A$5:$A$12,0)),INDEX(등급!$I$5:$I$12,MATCH($D12,등급!$A$5:$A$12,0))&"개",INDEX(등급!$I$5:$I$12,MATCH($D12,등급!$A$5:$A$12,0))&"~"&INDEX(등급!$J$5:$J$12,MATCH($D12,등급!$A$5:$A$12,0))&"개")) -> 1개 | N12: =IF(INDEX(등급!$L$5:$L$12,MATCH($D12,등급!$A$5:$A$12,0))=0,"-",INDEX(등급!$K$5:$K$12,MATCH($D12,등급!$A$5:$A$12,0))&"~"&INDEX(등급!$L$5:$L$12,MATCH($D12,등급!$A$5:$A$12,0))&"개") -> 0~2개
A13: =장비_기본!B6 -> 맹세의 장검 | B13: =장비_기본!C6 -> 무기 | C13: =장비_기본!D6 -> 탱커 | D13: UC | E13: =장비_기본!F6 -> 공격력 | F13: =장비_기본!G6*INDEX(등급!$C$5:$C$12,MATCH($D13,등급!$A$5:$A$12,0)) -> 2.2 | G13: =장비_기본!H6 -> 받는 피해 감소 | H13: =장비_기본!I6*INDEX(등급!$C$5:$C$12,MATCH($D13,등급!$A$5:$A$12,0)) -> 0.006 | I13: =장비_기본!J6 -> ① 도발 중 받는 피해 감소 +[값]%p | J13: =ROUND(장비_기본!K6*INDEX(등급!$F$5:$F$12,MATCH($D13,등급!$A$5:$A$12,0)),1) -> 3 | K13: =INDEX(등급!$D$5:$D$12,MATCH($D13,등급!$A$5:$A$12,0)) -> 0 | L13: =IF(INDEX(등급!$H$5:$H$12,MATCH($D13,등급!$A$5:$A$12,0))=0,"-",IF(INDEX(등급!$G$5:$G$12,MATCH($D13,등급!$A$5:$A$12,0))=INDEX(등급!$H$5:$H$12,MATCH($D13,등급!$A$5:$A$12,0)),INDEX(등급!$G$5:$G$12,MATCH($D13,등급!$A$5:$A$12,0))&"칸",INDEX(등급!$G$5:$G$12,MATCH($D13,등급!$A$5:$A$12,0))&"~"&INDEX(등급!$H$5:$H$12,MATCH($D13,등급!$A$5:$A$12,0))&"칸")) -> - | M13: =IF(INDEX(등급!$J$5:$J$12,MATCH($D13,등급!$A$5:$A$12,0))=0,"-",IF(INDEX(등급!$I$5:$I$12,MATCH($D13,등급!$A$5:$A$12,0))=INDEX(등급!$J$5:$J$12,MATCH($D13,등급!$A$5:$A$12,0)),INDEX(등급!$I$5:$I$12,MATCH($D13,등급!$A$5:$A$12,0))&"개",INDEX(등급!$I$5:$I$12,MATCH($D13,등급!$A$5:$A$12,0))&"~"&INDEX(등급!$J$5:$J$12,MATCH($D13,등급!$A$5:$A$12,0))&"개")) -> - | N13: =IF(INDEX(등급!$L$5:$L$12,MATCH($D13,등급!$A$5:$A$12,0))=0,"-",INDEX(등급!$K$5:$K$12,MATCH($D13,등급!$A$5:$A$12,0))&"~"&INDEX(등급!$L$5:$L$12,MATCH($D13,등급!$A$5:$A$12,0))&"개") -> -
A14: =장비_기본!B6 -> 맹세의 장검 | B14: =장비_기본!C6 -> 무기 | C14: =장비_기본!D6 -> 탱커 | D14: C | E14: =장비_기본!F6 -> 공격력 | F14: =장비_기본!G6*INDEX(등급!$C$5:$C$12,MATCH($D14,등급!$A$5:$A$12,0)) -> 3.19 | G14: =장비_기본!H6 -> 받는 피해 감소 | H14: =장비_기본!I6*INDEX(등급!$C$5:$C$12,MATCH($D14,등급!$A$5:$A$12,0)) -> 0.0087 | I14: =장비_기본!J6 -> ① 도발 중 받는 피해 감소 +[값]%p | J14: =ROUND(장비_기본!K6*INDEX(등급!$F$5:$F$12,MATCH($D14,등급!$A$5:$A$12,0)),1) -> 4.1 | K14: =INDEX(등급!$D$5:$D$12,MATCH($D14,등급!$A$5:$A$12,0)) -> 0 | L14: =IF(INDEX(등급!$H$5:$H$12,MATCH($D14,등급!$A$5:$A$12,0))=0,"-",IF(INDEX(등급!$G$5:$G$12,MATCH($D14,등급!$A$5:$A$12,0))=INDEX(등급!$H$5:$H$12,MATCH($D14,등급!$A$5:$A$12,0)),INDEX(등급!$G$5:$G$12,MATCH($D14,등급!$A$5:$A$12,0))&"칸",INDEX(등급!$G$5:$G$12,MATCH($D14,등급!$A$5:$A$12,0))&"~"&INDEX(등급!$H$5:$H$12,MATCH($D14,등급!$A$5:$A$12,0))&"칸")) -> - | M14: =IF(INDEX(등급!$J$5:$J$12,MATCH($D14,등급!$A$5:$A$12,0))=0,"-",IF(INDEX(등급!$I$5:$I$12,MATCH($D14,등급!$A$5:$A$12,0))=INDEX(등급!$J$5:$J$12,MATCH($D14,등급!$A$5:$A$12,0)),INDEX(등급!$I$5:$I$12,MATCH($D14,등급!$A$5:$A$12,0))&"개",INDEX(등급!$I$5:$I$12,MATCH($D14,등급!$A$5:$A$12,0))&"~"&INDEX(등급!$J$5:$J$12,MATCH($D14,등급!$A$5:$A$12,0))&"개")) -> - | N14: =IF(INDEX(등급!$L$5:$L$12,MATCH($D14,등급!$A$5:$A$12,0))=0,"-",INDEX(등급!$K$5:$K$12,MATCH($D14,등급!$A$5:$A$12,0))&"~"&INDEX(등급!$L$5:$L$12,MATCH($D14,등급!$A$5:$A$12,0))&"개") -> -
A15: =장비_기본!B6 -> 맹세의 장검 | B15: =장비_기본!C6 -> 무기 | C15: =장비_기본!D6 -> 탱커 | D15: R | E15: =장비_기본!F6 -> 공격력 | F15: =장비_기본!G6*INDEX(등급!$C$5:$C$12,MATCH($D15,등급!$A$5:$A$12,0)) -> 3.74 | G15: =장비_기본!H6 -> 받는 피해 감소 | H15: =장비_기본!I6*INDEX(등급!$C$5:$C$12,MATCH($D15,등급!$A$5:$A$12,0)) -> 0.0102 | I15: =장비_기본!J6 -> ① 도발 중 받는 피해 감소 +[값]%p | J15: =ROUND(장비_기본!K6*INDEX(등급!$F$5:$F$12,MATCH($D15,등급!$A$5:$A$12,0)),1) -> 4.5 | K15: =INDEX(등급!$D$5:$D$12,MATCH($D15,등급!$A$5:$A$12,0)) -> 1 | L15: =IF(INDEX(등급!$H$5:$H$12,MATCH($D15,등급!$A$5:$A$12,0))=0,"-",IF(INDEX(등급!$G$5:$G$12,MATCH($D15,등급!$A$5:$A$12,0))=INDEX(등급!$H$5:$H$12,MATCH($D15,등급!$A$5:$A$12,0)),INDEX(등급!$G$5:$G$12,MATCH($D15,등급!$A$5:$A$12,0))&"칸",INDEX(등급!$G$5:$G$12,MATCH($D15,등급!$A$5:$A$12,0))&"~"&INDEX(등급!$H$5:$H$12,MATCH($D15,등급!$A$5:$A$12,0))&"칸")) -> - | M15: =IF(INDEX(등급!$J$5:$J$12,MATCH($D15,등급!$A$5:$A$12,0))=0,"-",IF(INDEX(등급!$I$5:$I$12,MATCH($D15,등급!$A$5:$A$12,0))=INDEX(등급!$J$5:$J$12,MATCH($D15,등급!$A$5:$A$12,0)),INDEX(등급!$I$5:$I$12,MATCH($D15,등급!$A$5:$A$12,0))&"개",INDEX(등급!$I$5:$I$12,MATCH($D15,등급!$A$5:$A$12,0))&"~"&INDEX(등급!$J$5:$J$12,MATCH($D15,등급!$A$5:$A$12,0))&"개")) -> - | N15: =IF(INDEX(등급!$L$5:$L$12,MATCH($D15,등급!$A$5:$A$12,0))=0,"-",INDEX(등급!$K$5:$K$12,MATCH($D15,등급!$A$5:$A$12,0))&"~"&INDEX(등급!$L$5:$L$12,MATCH($D15,등급!$A$5:$A$12,0))&"개") -> -
A16: =장비_기본!B6 -> 맹세의 장검 | B16: =장비_기본!C6 -> 무기 | C16: =장비_기본!D6 -> 탱커 | D16: SR | E16: =장비_기본!F6 -> 공격력 | F16: =장비_기본!G6*INDEX(등급!$C$5:$C$12,MATCH($D16,등급!$A$5:$A$12,0)) -> 4.62 | G16: =장비_기본!H6 -> 받는 피해 감소 | H16: =장비_기본!I6*INDEX(등급!$C$5:$C$12,MATCH($D16,등급!$A$5:$A$12,0)) -> 0.0126 | I16: =장비_기본!J6 -> ① 도발 중 받는 피해 감소 +[값]%p | J16: =ROUND(장비_기본!K6*INDEX(등급!$F$5:$F$12,MATCH($D16,등급!$A$5:$A$12,0)),1) -> 5.3 | K16: =INDEX(등급!$D$5:$D$12,MATCH($D16,등급!$A$5:$A$12,0)) -> 2 | L16: =IF(INDEX(등급!$H$5:$H$12,MATCH($D16,등급!$A$5:$A$12,0))=0,"-",IF(INDEX(등급!$G$5:$G$12,MATCH($D16,등급!$A$5:$A$12,0))=INDEX(등급!$H$5:$H$12,MATCH($D16,등급!$A$5:$A$12,0)),INDEX(등급!$G$5:$G$12,MATCH($D16,등급!$A$5:$A$12,0))&"칸",INDEX(등급!$G$5:$G$12,MATCH($D16,등급!$A$5:$A$12,0))&"~"&INDEX(등급!$H$5:$H$12,MATCH($D16,등급!$A$5:$A$12,0))&"칸")) -> - | M16: =IF(INDEX(등급!$J$5:$J$12,MATCH($D16,등급!$A$5:$A$12,0))=0,"-",IF(INDEX(등급!$I$5:$I$12,MATCH($D16,등급!$A$5:$A$12,0))=INDEX(등급!$J$5:$J$12,MATCH($D16,등급!$A$5:$A$12,0)),INDEX(등급!$I$5:$I$12,MATCH($D16,등급!$A$5:$A$12,0))&"개",INDEX(등급!$I$5:$I$12,MATCH($D16,등급!$A$5:$A$12,0))&"~"&INDEX(등급!$J$5:$J$12,MATCH($D16,등급!$A$5:$A$12,0))&"개")) -> - | N16: =IF(INDEX(등급!$L$5:$L$12,MATCH($D16,등급!$A$5:$A$12,0))=0,"-",INDEX(등급!$K$5:$K$12,MATCH($D16,등급!$A$5:$A$12,0))&"~"&INDEX(등급!$L$5:$L$12,MATCH($D16,등급!$A$5:$A$12,0))&"개") -> -
A17: =장비_기본!B6 -> 맹세의 장검 | B17: =장비_기본!C6 -> 무기 | C17: =장비_기본!D6 -> 탱커 | D17: SSR | E17: =장비_기본!F6 -> 공격력 | F17: =장비_기본!G6*INDEX(등급!$C$5:$C$12,MATCH($D17,등급!$A$5:$A$12,0)) -> 5.61 | G17: =장비_기본!H6 -> 받는 피해 감소 | H17: =장비_기본!I6*INDEX(등급!$C$5:$C$12,MATCH($D17,등급!$A$5:$A$12,0)) -> 0.0153 | I17: =장비_기본!J6 -> ① 도발 중 받는 피해 감소 +[값]%p | J17: =ROUND(장비_기본!K6*INDEX(등급!$F$5:$F$12,MATCH($D17,등급!$A$5:$A$12,0)),1) -> 6 | K17: =INDEX(등급!$D$5:$D$12,MATCH($D17,등급!$A$5:$A$12,0)) -> 3 | L17: =IF(INDEX(등급!$H$5:$H$12,MATCH($D17,등급!$A$5:$A$12,0))=0,"-",IF(INDEX(등급!$G$5:$G$12,MATCH($D17,등급!$A$5:$A$12,0))=INDEX(등급!$H$5:$H$12,MATCH($D17,등급!$A$5:$A$12,0)),INDEX(등급!$G$5:$G$12,MATCH($D17,등급!$A$5:$A$12,0))&"칸",INDEX(등급!$G$5:$G$12,MATCH($D17,등급!$A$5:$A$12,0))&"~"&INDEX(등급!$H$5:$H$12,MATCH($D17,등급!$A$5:$A$12,0))&"칸")) -> - | M17: =IF(INDEX(등급!$J$5:$J$12,MATCH($D17,등급!$A$5:$A$12,0))=0,"-",IF(INDEX(등급!$I$5:$I$12,MATCH($D17,등급!$A$5:$A$12,0))=INDEX(등급!$J$5:$J$12,MATCH($D17,등급!$A$5:$A$12,0)),INDEX(등급!$I$5:$I$12,MATCH($D17,등급!$A$5:$A$12,0))&"개",INDEX(등급!$I$5:$I$12,MATCH($D17,등급!$A$5:$A$12,0))&"~"&INDEX(등급!$J$5:$J$12,MATCH($D17,등급!$A$5:$A$12,0))&"개")) -> - | N17: =IF(INDEX(등급!$L$5:$L$12,MATCH($D17,등급!$A$5:$A$12,0))=0,"-",INDEX(등급!$K$5:$K$12,MATCH($D17,등급!$A$5:$A$12,0))&"~"&INDEX(등급!$L$5:$L$12,MATCH($D17,등급!$A$5:$A$12,0))&"개") -> -
A18: =장비_기본!B6 -> 맹세의 장검 | B18: =장비_기본!C6 -> 무기 | C18: =장비_기본!D6 -> 탱커 | D18: UR | E18: =장비_기본!F6 -> 공격력 | F18: =장비_기본!G6*INDEX(등급!$C$5:$C$12,MATCH($D18,등급!$A$5:$A$12,0)) -> 6.71 | G18: =장비_기본!H6 -> 받는 피해 감소 | H18: =장비_기본!I6*INDEX(등급!$C$5:$C$12,MATCH($D18,등급!$A$5:$A$12,0)) -> 0.0183 | I18: =장비_기본!J6 -> ① 도발 중 받는 피해 감소 +[값]%p | J18: =ROUND(장비_기본!K6*INDEX(등급!$F$5:$F$12,MATCH($D18,등급!$A$5:$A$12,0)),1) -> 6.9 | K18: =INDEX(등급!$D$5:$D$12,MATCH($D18,등급!$A$5:$A$12,0)) -> 4 | L18: =IF(INDEX(등급!$H$5:$H$12,MATCH($D18,등급!$A$5:$A$12,0))=0,"-",IF(INDEX(등급!$G$5:$G$12,MATCH($D18,등급!$A$5:$A$12,0))=INDEX(등급!$H$5:$H$12,MATCH($D18,등급!$A$5:$A$12,0)),INDEX(등급!$G$5:$G$12,MATCH($D18,등급!$A$5:$A$12,0))&"칸",INDEX(등급!$G$5:$G$12,MATCH($D18,등급!$A$5:$A$12,0))&"~"&INDEX(등급!$H$5:$H$12,MATCH($D18,등급!$A$5:$A$12,0))&"칸")) -> - | M18: =IF(INDEX(등급!$J$5:$J$12,MATCH($D18,등급!$A$5:$A$12,0))=0,"-",IF(INDEX(등급!$I$5:$I$12,MATCH($D18,등급!$A$5:$A$12,0))=INDEX(등급!$J$5:$J$12,MATCH($D18,등급!$A$5:$A$12,0)),INDEX(등급!$I$5:$I$12,MATCH($D18,등급!$A$5:$A$12,0))&"개",INDEX(등급!$I$5:$I$12,MATCH($D18,등급!$A$5:$A$12,0))&"~"&INDEX(등급!$J$5:$J$12,MATCH($D18,등급!$A$5:$A$12,0))&"개")) -> - | N18: =IF(INDEX(등급!$L$5:$L$12,MATCH($D18,등급!$A$5:$A$12,0))=0,"-",INDEX(등급!$K$5:$K$12,MATCH($D18,등급!$A$5:$A$12,0))&"~"&INDEX(등급!$L$5:$L$12,MATCH($D18,등급!$A$5:$A$12,0))&"개") -> -
A19: =장비_기본!B6 -> 맹세의 장검 | B19: =장비_기본!C6 -> 무기 | C19: =장비_기본!D6 -> 탱커 | D19: L | E19: =장비_기본!F6 -> 공격력 | F19: =장비_기본!G6*INDEX(등급!$C$5:$C$12,MATCH($D19,등급!$A$5:$A$12,0)) -> 7.04 | G19: =장비_기본!H6 -> 받는 피해 감소 | H19: =장비_기본!I6*INDEX(등급!$C$5:$C$12,MATCH($D19,등급!$A$5:$A$12,0)) -> 0.0192 | I19: =장비_기본!J6 -> ① 도발 중 받는 피해 감소 +[값]%p | J19: =ROUND(장비_기본!K6*INDEX(등급!$F$5:$F$12,MATCH($D19,등급!$A$5:$A$12,0)),1) -> 8 | K19: =INDEX(등급!$D$5:$D$12,MATCH($D19,등급!$A$5:$A$12,0)) -> 4 | L19: =IF(INDEX(등급!$H$5:$H$12,MATCH($D19,등급!$A$5:$A$12,0))=0,"-",IF(INDEX(등급!$G$5:$G$12,MATCH($D19,등급!$A$5:$A$12,0))=INDEX(등급!$H$5:$H$12,MATCH($D19,등급!$A$5:$A$12,0)),INDEX(등급!$G$5:$G$12,MATCH($D19,등급!$A$5:$A$12,0))&"칸",INDEX(등급!$G$5:$G$12,MATCH($D19,등급!$A$5:$A$12,0))&"~"&INDEX(등급!$H$5:$H$12,MATCH($D19,등급!$A$5:$A$12,0))&"칸")) -> 1칸 | M19: =IF(INDEX(등급!$J$5:$J$12,MATCH($D19,등급!$A$5:$A$12,0))=0,"-",IF(INDEX(등급!$I$5:$I$12,MATCH($D19,등급!$A$5:$A$12,0))=INDEX(등급!$J$5:$J$12,MATCH($D19,등급!$A$5:$A$12,0)),INDEX(등급!$I$5:$I$12,MATCH($D19,등급!$A$5:$A$12,0))&"개",INDEX(등급!$I$5:$I$12,MATCH($D19,등급!$A$5:$A$12,0))&"~"&INDEX(등급!$J$5:$J$12,MATCH($D19,등급!$A$5:$A$12,0))&"개")) -> 0~1개 | N19: =IF(INDEX(등급!$L$5:$L$12,MATCH($D19,등급!$A$5:$A$12,0))=0,"-",INDEX(등급!$K$5:$K$12,MATCH($D19,등급!$A$5:$A$12,0))&"~"&INDEX(등급!$L$5:$L$12,MATCH($D19,등급!$A$5:$A$12,0))&"개") -> 0~1개
A20: =장비_기본!B6 -> 맹세의 장검 | B20: =장비_기본!C6 -> 무기 | C20: =장비_기본!D6 -> 탱커 | D20: E | E20: =장비_기본!F6 -> 공격력 | F20: =장비_기본!G6*INDEX(등급!$C$5:$C$12,MATCH($D20,등급!$A$5:$A$12,0)) -> 7.26 | G20: =장비_기본!H6 -> 받는 피해 감소 | H20: =장비_기본!I6*INDEX(등급!$C$5:$C$12,MATCH($D20,등급!$A$5:$A$12,0)) -> 0.0198 | I20: =장비_기본!J6 -> ① 도발 중 받는 피해 감소 +[값]%p | J20: =ROUND(장비_기본!K6*INDEX(등급!$F$5:$F$12,MATCH($D20,등급!$A$5:$A$12,0)),1) -> 9 | K20: =INDEX(등급!$D$5:$D$12,MATCH($D20,등급!$A$5:$A$12,0)) -> 4 | L20: =IF(INDEX(등급!$H$5:$H$12,MATCH($D20,등급!$A$5:$A$12,0))=0,"-",IF(INDEX(등급!$G$5:$G$12,MATCH($D20,등급!$A$5:$A$12,0))=INDEX(등급!$H$5:$H$12,MATCH($D20,등급!$A$5:$A$12,0)),INDEX(등급!$G$5:$G$12,MATCH($D20,등급!$A$5:$A$12,0))&"칸",INDEX(등급!$G$5:$G$12,MATCH($D20,등급!$A$5:$A$12,0))&"~"&INDEX(등급!$H$5:$H$12,MATCH($D20,등급!$A$5:$A$12,0))&"칸")) -> 1~3칸 | M20: =IF(INDEX(등급!$J$5:$J$12,MATCH($D20,등급!$A$5:$A$12,0))=0,"-",IF(INDEX(등급!$I$5:$I$12,MATCH($D20,등급!$A$5:$A$12,0))=INDEX(등급!$J$5:$J$12,MATCH($D20,등급!$A$5:$A$12,0)),INDEX(등급!$I$5:$I$12,MATCH($D20,등급!$A$5:$A$12,0))&"개",INDEX(등급!$I$5:$I$12,MATCH($D20,등급!$A$5:$A$12,0))&"~"&INDEX(등급!$J$5:$J$12,MATCH($D20,등급!$A$5:$A$12,0))&"개")) -> 1개 | N20: =IF(INDEX(등급!$L$5:$L$12,MATCH($D20,등급!$A$5:$A$12,0))=0,"-",INDEX(등급!$K$5:$K$12,MATCH($D20,등급!$A$5:$A$12,0))&"~"&INDEX(등급!$L$5:$L$12,MATCH($D20,등급!$A$5:$A$12,0))&"개") -> 0~2개
A21: =장비_기본!B7 -> 성채의 철퇴 | B21: =장비_기본!C7 -> 무기 | C21: =장비_기본!D7 -> 탱커 | D21: UC | E21: =장비_기본!F7 -> 공격력 | F21: =장비_기본!G7*INDEX(등급!$C$5:$C$12,MATCH($D21,등급!$A$5:$A$12,0)) -> 2.2 | G21: =장비_기본!H7 -> 받는 피해 감소 | H21: =장비_기본!I7*INDEX(등급!$C$5:$C$12,MATCH($D21,등급!$A$5:$A$12,0)) -> 0.006 | I21: =장비_기본!J7 -> 평타 적중 시 [값]% 확률로 0.6초 기절 | J21: =ROUND(장비_기본!K7*INDEX(등급!$F$5:$F$12,MATCH($D21,등급!$A$5:$A$12,0)),1) -> 3 | K21: =INDEX(등급!$D$5:$D$12,MATCH($D21,등급!$A$5:$A$12,0)) -> 0 | L21: =IF(INDEX(등급!$H$5:$H$12,MATCH($D21,등급!$A$5:$A$12,0))=0,"-",IF(INDEX(등급!$G$5:$G$12,MATCH($D21,등급!$A$5:$A$12,0))=INDEX(등급!$H$5:$H$12,MATCH($D21,등급!$A$5:$A$12,0)),INDEX(등급!$G$5:$G$12,MATCH($D21,등급!$A$5:$A$12,0))&"칸",INDEX(등급!$G$5:$G$12,MATCH($D21,등급!$A$5:$A$12,0))&"~"&INDEX(등급!$H$5:$H$12,MATCH($D21,등급!$A$5:$A$12,0))&"칸")) -> - | M21: =IF(INDEX(등급!$J$5:$J$12,MATCH($D21,등급!$A$5:$A$12,0))=0,"-",IF(INDEX(등급!$I$5:$I$12,MATCH($D21,등급!$A$5:$A$12,0))=INDEX(등급!$J$5:$J$12,MATCH($D21,등급!$A$5:$A$12,0)),INDEX(등급!$I$5:$I$12,MATCH($D21,등급!$A$5:$A$12,0))&"개",INDEX(등급!$I$5:$I$12,MATCH($D21,등급!$A$5:$A$12,0))&"~"&INDEX(등급!$J$5:$J$12,MATCH($D21,등급!$A$5:$A$12,0))&"개")) -> - | N21: =IF(INDEX(등급!$L$5:$L$12,MATCH($D21,등급!$A$5:$A$12,0))=0,"-",INDEX(등급!$K$5:$K$12,MATCH($D21,등급!$A$5:$A$12,0))&"~"&INDEX(등급!$L$5:$L$12,MATCH($D21,등급!$A$5:$A$12,0))&"개") -> -
A22: =장비_기본!B7 -> 성채의 철퇴 | B22: =장비_기본!C7 -> 무기 | C22: =장비_기본!D7 -> 탱커 | D22: C | E22: =장비_기본!F7 -> 공격력 | F22: =장비_기본!G7*INDEX(등급!$C$5:$C$12,MATCH($D22,등급!$A$5:$A$12,0)) -> 3.19 | G22: =장비_기본!H7 -> 받는 피해 감소 | H22: =장비_기본!I7*INDEX(등급!$C$5:$C$12,MATCH($D22,등급!$A$5:$A$12,0)) -> 0.0087 | I22: =장비_기본!J7 -> 평타 적중 시 [값]% 확률로 0.6초 기절 | J22: =ROUND(장비_기본!K7*INDEX(등급!$F$5:$F$12,MATCH($D22,등급!$A$5:$A$12,0)),1) -> 4.1 | K22: =INDEX(등급!$D$5:$D$12,MATCH($D22,등급!$A$5:$A$12,0)) -> 0 | L22: =IF(INDEX(등급!$H$5:$H$12,MATCH($D22,등급!$A$5:$A$12,0))=0,"-",IF(INDEX(등급!$G$5:$G$12,MATCH($D22,등급!$A$5:$A$12,0))=INDEX(등급!$H$5:$H$12,MATCH($D22,등급!$A$5:$A$12,0)),INDEX(등급!$G$5:$G$12,MATCH($D22,등급!$A$5:$A$12,0))&"칸",INDEX(등급!$G$5:$G$12,MATCH($D22,등급!$A$5:$A$12,0))&"~"&INDEX(등급!$H$5:$H$12,MATCH($D22,등급!$A$5:$A$12,0))&"칸")) -> - | M22: =IF(INDEX(등급!$J$5:$J$12,MATCH($D22,등급!$A$5:$A$12,0))=0,"-",IF(INDEX(등급!$I$5:$I$12,MATCH($D22,등급!$A$5:$A$12,0))=INDEX(등급!$J$5:$J$12,MATCH($D22,등급!$A$5:$A$12,0)),INDEX(등급!$I$5:$I$12,MATCH($D22,등급!$A$5:$A$12,0))&"개",INDEX(등급!$I$5:$I$12,MATCH($D22,등급!$A$5:$A$12,0))&"~"&INDEX(등급!$J$5:$J$12,MATCH($D22,등급!$A$5:$A$12,0))&"개")) -> - | N22: =IF(INDEX(등급!$L$5:$L$12,MATCH($D22,등급!$A$5:$A$12,0))=0,"-",INDEX(등급!$K$5:$K$12,MATCH($D22,등급!$A$5:$A$12,0))&"~"&INDEX(등급!$L$5:$L$12,MATCH($D22,등급!$A$5:$A$12,0))&"개") -> -
A23: =장비_기본!B7 -> 성채의 철퇴 | B23: =장비_기본!C7 -> 무기 | C23: =장비_기본!D7 -> 탱커 | D23: R | E23: =장비_기본!F7 -> 공격력 | F23: =장비_기본!G7*INDEX(등급!$C$5:$C$12,MATCH($D23,등급!$A$5:$A$12,0)) -> 3.74 | G23: =장비_기본!H7 -> 받는 피해 감소 | H23: =장비_기본!I7*INDEX(등급!$C$5:$C$12,MATCH($D23,등급!$A$5:$A$12,0)) -> 0.0102 | I23: =장비_기본!J7 -> 평타 적중 시 [값]% 확률로 0.6초 기절 | J23: =ROUND(장비_기본!K7*INDEX(등급!$F$5:$F$12,MATCH($D23,등급!$A$5:$A$12,0)),1) -> 4.5 | K23: =INDEX(등급!$D$5:$D$12,MATCH($D23,등급!$A$5:$A$12,0)) -> 1 | L23: =IF(INDEX(등급!$H$5:$H$12,MATCH($D23,등급!$A$5:$A$12,0))=0,"-",IF(INDEX(등급!$G$5:$G$12,MATCH($D23,등급!$A$5:$A$12,0))=INDEX(등급!$H$5:$H$12,MATCH($D23,등급!$A$5:$A$12,0)),INDEX(등급!$G$5:$G$12,MATCH($D23,등급!$A$5:$A$12,0))&"칸",INDEX(등급!$G$5:$G$12,MATCH($D23,등급!$A$5:$A$12,0))&"~"&INDEX(등급!$H$5:$H$12,MATCH($D23,등급!$A$5:$A$12,0))&"칸")) -> - | M23: =IF(INDEX(등급!$J$5:$J$12,MATCH($D23,등급!$A$5:$A$12,0))=0,"-",IF(INDEX(등급!$I$5:$I$12,MATCH($D23,등급!$A$5:$A$12,0))=INDEX(등급!$J$5:$J$12,MATCH($D23,등급!$A$5:$A$12,0)),INDEX(등급!$I$5:$I$12,MATCH($D23,등급!$A$5:$A$12,0))&"개",INDEX(등급!$I$5:$I$12,MATCH($D23,등급!$A$5:$A$12,0))&"~"&INDEX(등급!$J$5:$J$12,MATCH($D23,등급!$A$5:$A$12,0))&"개")) -> - | N23: =IF(INDEX(등급!$L$5:$L$12,MATCH($D23,등급!$A$5:$A$12,0))=0,"-",INDEX(등급!$K$5:$K$12,MATCH($D23,등급!$A$5:$A$12,0))&"~"&INDEX(등급!$L$5:$L$12,MATCH($D23,등급!$A$5:$A$12,0))&"개") -> -
A24: =장비_기본!B7 -> 성채의 철퇴 | B24: =장비_기본!C7 -> 무기 | C24: =장비_기본!D7 -> 탱커 | D24: SR | E24: =장비_기본!F7 -> 공격력 | F24: =장비_기본!G7*INDEX(등급!$C$5:$C$12,MATCH($D24,등급!$A$5:$A$12,0)) -> 4.62 | G24: =장비_기본!H7 -> 받는 피해 감소 | H24: =장비_기본!I7*INDEX(등급!$C$5:$C$12,MATCH($D24,등급!$A$5:$A$12,0)) -> 0.0126 | I24: =장비_기본!J7 -> 평타 적중 시 [값]% 확률로 0.6초 기절 | J24: =ROUND(장비_기본!K7*INDEX(등급!$F$5:$F$12,MATCH($D24,등급!$A$5:$A$12,0)),1) -> 5.3 | K24: =INDEX(등급!$D$5:$D$12,MATCH($D24,등급!$A$5:$A$12,0)) -> 2 | L24: =IF(INDEX(등급!$H$5:$H$12,MATCH($D24,등급!$A$5:$A$12,0))=0,"-",IF(INDEX(등급!$G$5:$G$12,MATCH($D24,등급!$A$5:$A$12,0))=INDEX(등급!$H$5:$H$12,MATCH($D24,등급!$A$5:$A$12,0)),INDEX(등급!$G$5:$G$12,MATCH($D24,등급!$A$5:$A$12,0))&"칸",INDEX(등급!$G$5:$G$12,MATCH($D24,등급!$A$5:$A$12,0))&"~"&INDEX(등급!$H$5:$H$12,MATCH($D24,등급!$A$5:$A$12,0))&"칸")) -> - | M24: =IF(INDEX(등급!$J$5:$J$12,MATCH($D24,등급!$A$5:$A$12,0))=0,"-",IF(INDEX(등급!$I$5:$I$12,MATCH($D24,등급!$A$5:$A$12,0))=INDEX(등급!$J$5:$J$12,MATCH($D24,등급!$A$5:$A$12,0)),INDEX(등급!$I$5:$I$12,MATCH($D24,등급!$A$5:$A$12,0))&"개",INDEX(등급!$I$5:$I$12,MATCH($D24,등급!$A$5:$A$12,0))&"~"&INDEX(등급!$J$5:$J$12,MATCH($D24,등급!$A$5:$A$12,0))&"개")) -> - | N24: =IF(INDEX(등급!$L$5:$L$12,MATCH($D24,등급!$A$5:$A$12,0))=0,"-",INDEX(등급!$K$5:$K$12,MATCH($D24,등급!$A$5:$A$12,0))&"~"&INDEX(등급!$L$5:$L$12,MATCH($D24,등급!$A$5:$A$12,0))&"개") -> -
A25: =장비_기본!B7 -> 성채의 철퇴 | B25: =장비_기본!C7 -> 무기 | C25: =장비_기본!D7 -> 탱커 | D25: SSR | E25: =장비_기본!F7 -> 공격력 | F25: =장비_기본!G7*INDEX(등급!$C$5:$C$12,MATCH($D25,등급!$A$5:$A$12,0)) -> 5.61 | G25: =장비_기본!H7 -> 받는 피해 감소 | H25: =장비_기본!I7*INDEX(등급!$C$5:$C$12,MATCH($D25,등급!$A$5:$A$12,0)) -> 0.0153 | I25: =장비_기본!J7 -> 평타 적중 시 [값]% 확률로 0.6초 기절 | J25: =ROUND(장비_기본!K7*INDEX(등급!$F$5:$F$12,MATCH($D25,등급!$A$5:$A$12,0)),1) -> 6 | K25: =INDEX(등급!$D$5:$D$12,MATCH($D25,등급!$A$5:$A$12,0)) -> 3 | L25: =IF(INDEX(등급!$H$5:$H$12,MATCH($D25,등급!$A$5:$A$12,0))=0,"-",IF(INDEX(등급!$G$5:$G$12,MATCH($D25,등급!$A$5:$A$12,0))=INDEX(등급!$H$5:$H$12,MATCH($D25,등급!$A$5:$A$12,0)),INDEX(등급!$G$5:$G$12,MATCH($D25,등급!$A$5:$A$12,0))&"칸",INDEX(등급!$G$5:$G$12,MATCH($D25,등급!$A$5:$A$12,0))&"~"&INDEX(등급!$H$5:$H$12,MATCH($D25,등급!$A$5:$A$12,0))&"칸")) -> - | M25: =IF(INDEX(등급!$J$5:$J$12,MATCH($D25,등급!$A$5:$A$12,0))=0,"-",IF(INDEX(등급!$I$5:$I$12,MATCH($D25,등급!$A$5:$A$12,0))=INDEX(등급!$J$5:$J$12,MATCH($D25,등급!$A$5:$A$12,0)),INDEX(등급!$I$5:$I$12,MATCH($D25,등급!$A$5:$A$12,0))&"개",INDEX(등급!$I$5:$I$12,MATCH($D25,등급!$A$5:$A$12,0))&"~"&INDEX(등급!$J$5:$J$12,MATCH($D25,등급!$A$5:$A$12,0))&"개")) -> - | N25: =IF(INDEX(등급!$L$5:$L$12,MATCH($D25,등급!$A$5:$A$12,0))=0,"-",INDEX(등급!$K$5:$K$12,MATCH($D25,등급!$A$5:$A$12,0))&"~"&INDEX(등급!$L$5:$L$12,MATCH($D25,등급!$A$5:$A$12,0))&"개") -> -
A26: =장비_기본!B7 -> 성채의 철퇴 | B26: =장비_기본!C7 -> 무기 | C26: =장비_기본!D7 -> 탱커 | D26: UR | E26: =장비_기본!F7 -> 공격력 | F26: =장비_기본!G7*INDEX(등급!$C$5:$C$12,MATCH($D26,등급!$A$5:$A$12,0)) -> 6.71 | G26: =장비_기본!H7 -> 받는 피해 감소 | H26: =장비_기본!I7*INDEX(등급!$C$5:$C$12,MATCH($D26,등급!$A$5:$A$12,0)) -> 0.0183 | I26: =장비_기본!J7 -> 평타 적중 시 [값]% 확률로 0.6초 기절 | J26: =ROUND(장비_기본!K7*INDEX(등급!$F$5:$F$12,MATCH($D26,등급!$A$5:$A$12,0)),1) -> 6.9 | K26: =INDEX(등급!$D$5:$D$12,MATCH($D26,등급!$A$5:$A$12,0)) -> 4 | L26: =IF(INDEX(등급!$H$5:$H$12,MATCH($D26,등급!$A$5:$A$12,0))=0,"-",IF(INDEX(등급!$G$5:$G$12,MATCH($D26,등급!$A$5:$A$12,0))=INDEX(등급!$H$5:$H$12,MATCH($D26,등급!$A$5:$A$12,0)),INDEX(등급!$G$5:$G$12,MATCH($D26,등급!$A$5:$A$12,0))&"칸",INDEX(등급!$G$5:$G$12,MATCH($D26,등급!$A$5:$A$12,0))&"~"&INDEX(등급!$H$5:$H$12,MATCH($D26,등급!$A$5:$A$12,0))&"칸")) -> - | M26: =IF(INDEX(등급!$J$5:$J$12,MATCH($D26,등급!$A$5:$A$12,0))=0,"-",IF(INDEX(등급!$I$5:$I$12,MATCH($D26,등급!$A$5:$A$12,0))=INDEX(등급!$J$5:$J$12,MATCH($D26,등급!$A$5:$A$12,0)),INDEX(등급!$I$5:$I$12,MATCH($D26,등급!$A$5:$A$12,0))&"개",INDEX(등급!$I$5:$I$12,MATCH($D26,등급!$A$5:$A$12,0))&"~"&INDEX(등급!$J$5:$J$12,MATCH($D26,등급!$A$5:$A$12,0))&"개")) -> - | N26: =IF(INDEX(등급!$L$5:$L$12,MATCH($D26,등급!$A$5:$A$12,0))=0,"-",INDEX(등급!$K$5:$K$12,MATCH($D26,등급!$A$5:$A$12,0))&"~"&INDEX(등급!$L$5:$L$12,MATCH($D26,등급!$A$5:$A$12,0))&"개") -> -
A27: =장비_기본!B7 -> 성채의 철퇴 | B27: =장비_기본!C7 -> 무기 | C27: =장비_기본!D7 -> 탱커 | D27: L | E27: =장비_기본!F7 -> 공격력 | F27: =장비_기본!G7*INDEX(등급!$C$5:$C$12,MATCH($D27,등급!$A$5:$A$12,0)) -> 7.04 | G27: =장비_기본!H7 -> 받는 피해 감소 | H27: =장비_기본!I7*INDEX(등급!$C$5:$C$12,MATCH($D27,등급!$A$5:$A$12,0)) -> 0.0192 | I27: =장비_기본!J7 -> 평타 적중 시 [값]% 확률로 0.6초 기절 | J27: =ROUND(장비_기본!K7*INDEX(등급!$F$5:$F$12,MATCH($D27,등급!$A$5:$A$12,0)),1) -> 8 | K27: =INDEX(등급!$D$5:$D$12,MATCH($D27,등급!$A$5:$A$12,0)) -> 4 | L27: =IF(INDEX(등급!$H$5:$H$12,MATCH($D27,등급!$A$5:$A$12,0))=0,"-",IF(INDEX(등급!$G$5:$G$12,MATCH($D27,등급!$A$5:$A$12,0))=INDEX(등급!$H$5:$H$12,MATCH($D27,등급!$A$5:$A$12,0)),INDEX(등급!$G$5:$G$12,MATCH($D27,등급!$A$5:$A$12,0))&"칸",INDEX(등급!$G$5:$G$12,MATCH($D27,등급!$A$5:$A$12,0))&"~"&INDEX(등급!$H$5:$H$12,MATCH($D27,등급!$A$5:$A$12,0))&"칸")) -> 1칸 | M27: =IF(INDEX(등급!$J$5:$J$12,MATCH($D27,등급!$A$5:$A$12,0))=0,"-",IF(INDEX(등급!$I$5:$I$12,MATCH($D27,등급!$A$5:$A$12,0))=INDEX(등급!$J$5:$J$12,MATCH($D27,등급!$A$5:$A$12,0)),INDEX(등급!$I$5:$I$12,MATCH($D27,등급!$A$5:$A$12,0))&"개",INDEX(등급!$I$5:$I$12,MATCH($D27,등급!$A$5:$A$12,0))&"~"&INDEX(등급!$J$5:$J$12,MATCH($D27,등급!$A$5:$A$12,0))&"개")) -> 0~1개 | N27: =IF(INDEX(등급!$L$5:$L$12,MATCH($D27,등급!$A$5:$A$12,0))=0,"-",INDEX(등급!$K$5:$K$12,MATCH($D27,등급!$A$5:$A$12,0))&"~"&INDEX(등급!$L$5:$L$12,MATCH($D27,등급!$A$5:$A$12,0))&"개") -> 0~1개
A28: =장비_기본!B7 -> 성채의 철퇴 | B28: =장비_기본!C7 -> 무기 | C28: =장비_기본!D7 -> 탱커 | D28: E | E28: =장비_기본!F7 -> 공격력 | F28: =장비_기본!G7*INDEX(등급!$C$5:$C$12,MATCH($D28,등급!$A$5:$A$12,0)) -> 7.26 | G28: =장비_기본!H7 -> 받는 피해 감소 | H28: =장비_기본!I7*INDEX(등급!$C$5:$C$12,MATCH($D28,등급!$A$5:$A$12,0)) -> 0.0198 | I28: =장비_기본!J7 -> 평타 적중 시 [값]% 확률로 0.6초 기절 | J28: =ROUND(장비_기본!K7*INDEX(등급!$F$5:$F$12,MATCH($D28,등급!$A$5:$A$12,0)),1) -> 9 | K28: =INDEX(등급!$D$5:$D$12,MATCH($D28,등급!$A$5:$A$12,0)) -> 4 | L28: =IF(INDEX(등급!$H$5:$H$12,MATCH($D28,등급!$A$5:$A$12,0))=0,"-",IF(INDEX(등급!$G$5:$G$12,MATCH($D28,등급!$A$5:$A$12,0))=INDEX(등급!$H$5:$H$12,MATCH($D28,등급!$A$5:$A$12,0)),INDEX(등급!$G$5:$G$12,MATCH($D28,등급!$A$5:$A$12,0))&"칸",INDEX(등급!$G$5:$G$12,MATCH($D28,등급!$A$5:$A$12,0))&"~"&INDEX(등급!$H$5:$H$12,MATCH($D28,등급!$A$5:$A$12,0))&"칸")) -> 1~3칸 | M28: =IF(INDEX(등급!$J$5:$J$12,MATCH($D28,등급!$A$5:$A$12,0))=0,"-",IF(INDEX(등급!$I$5:$I$12,MATCH($D28,등급!$A$5:$A$12,0))=INDEX(등급!$J$5:$J$12,MATCH($D28,등급!$A$5:$A$12,0)),INDEX(등급!$I$5:$I$12,MATCH($D28,등급!$A$5:$A$12,0))&"개",INDEX(등급!$I$5:$I$12,MATCH($D28,등급!$A$5:$A$12,0))&"~"&INDEX(등급!$J$5:$J$12,MATCH($D28,등급!$A$5:$A$12,0))&"개")) -> 1개 | N28: =IF(INDEX(등급!$L$5:$L$12,MATCH($D28,등급!$A$5:$A$12,0))=0,"-",INDEX(등급!$K$5:$K$12,MATCH($D28,등급!$A$5:$A$12,0))&"~"&INDEX(등급!$L$5:$L$12,MATCH($D28,등급!$A$5:$A$12,0))&"개") -> 0~2개
A29: =장비_기본!B8 -> 성벽 판금갑 | B29: =장비_기본!C8 -> 갑옷 | C29: =장비_기본!D8 -> 탱커 | D29: UC | E29: =장비_기본!F8 -> 체력 | F29: =장비_기본!G8*INDEX(등급!$C$5:$C$12,MATCH($D29,등급!$A$5:$A$12,0)) -> 52 | G29: =장비_기본!H8 -> 받는 피해 감소 | H29: =장비_기본!I8*INDEX(등급!$C$5:$C$12,MATCH($D29,등급!$A$5:$A$12,0)) -> 0.006 | I29: =장비_기본!J8 -> 차지 공격 피해 -[값]% | J29: =ROUND(장비_기본!K8*INDEX(등급!$F$5:$F$12,MATCH($D29,등급!$A$5:$A$12,0)),1) -> 6 | K29: =INDEX(등급!$D$5:$D$12,MATCH($D29,등급!$A$5:$A$12,0)) -> 0 | L29: =IF(INDEX(등급!$H$5:$H$12,MATCH($D29,등급!$A$5:$A$12,0))=0,"-",IF(INDEX(등급!$G$5:$G$12,MATCH($D29,등급!$A$5:$A$12,0))=INDEX(등급!$H$5:$H$12,MATCH($D29,등급!$A$5:$A$12,0)),INDEX(등급!$G$5:$G$12,MATCH($D29,등급!$A$5:$A$12,0))&"칸",INDEX(등급!$G$5:$G$12,MATCH($D29,등급!$A$5:$A$12,0))&"~"&INDEX(등급!$H$5:$H$12,MATCH($D29,등급!$A$5:$A$12,0))&"칸")) -> - | M29: =IF(INDEX(등급!$J$5:$J$12,MATCH($D29,등급!$A$5:$A$12,0))=0,"-",IF(INDEX(등급!$I$5:$I$12,MATCH($D29,등급!$A$5:$A$12,0))=INDEX(등급!$J$5:$J$12,MATCH($D29,등급!$A$5:$A$12,0)),INDEX(등급!$I$5:$I$12,MATCH($D29,등급!$A$5:$A$12,0))&"개",INDEX(등급!$I$5:$I$12,MATCH($D29,등급!$A$5:$A$12,0))&"~"&INDEX(등급!$J$5:$J$12,MATCH($D29,등급!$A$5:$A$12,0))&"개")) -> - | N29: =IF(INDEX(등급!$L$5:$L$12,MATCH($D29,등급!$A$5:$A$12,0))=0,"-",INDEX(등급!$K$5:$K$12,MATCH($D29,등급!$A$5:$A$12,0))&"~"&INDEX(등급!$L$5:$L$12,MATCH($D29,등급!$A$5:$A$12,0))&"개") -> -
A30: =장비_기본!B8 -> 성벽 판금갑 | B30: =장비_기본!C8 -> 갑옷 | C30: =장비_기본!D8 -> 탱커 | D30: C | E30: =장비_기본!F8 -> 체력 | F30: =장비_기본!G8*INDEX(등급!$C$5:$C$12,MATCH($D30,등급!$A$5:$A$12,0)) -> 75.4 | G30: =장비_기본!H8 -> 받는 피해 감소 | H30: =장비_기본!I8*INDEX(등급!$C$5:$C$12,MATCH($D30,등급!$A$5:$A$12,0)) -> 0.0087 | I30: =장비_기본!J8 -> 차지 공격 피해 -[값]% | J30: =ROUND(장비_기본!K8*INDEX(등급!$F$5:$F$12,MATCH($D30,등급!$A$5:$A$12,0)),1) -> 8.1 | K30: =INDEX(등급!$D$5:$D$12,MATCH($D30,등급!$A$5:$A$12,0)) -> 0 | L30: =IF(INDEX(등급!$H$5:$H$12,MATCH($D30,등급!$A$5:$A$12,0))=0,"-",IF(INDEX(등급!$G$5:$G$12,MATCH($D30,등급!$A$5:$A$12,0))=INDEX(등급!$H$5:$H$12,MATCH($D30,등급!$A$5:$A$12,0)),INDEX(등급!$G$5:$G$12,MATCH($D30,등급!$A$5:$A$12,0))&"칸",INDEX(등급!$G$5:$G$12,MATCH($D30,등급!$A$5:$A$12,0))&"~"&INDEX(등급!$H$5:$H$12,MATCH($D30,등급!$A$5:$A$12,0))&"칸")) -> - | M30: =IF(INDEX(등급!$J$5:$J$12,MATCH($D30,등급!$A$5:$A$12,0))=0,"-",IF(INDEX(등급!$I$5:$I$12,MATCH($D30,등급!$A$5:$A$12,0))=INDEX(등급!$J$5:$J$12,MATCH($D30,등급!$A$5:$A$12,0)),INDEX(등급!$I$5:$I$12,MATCH($D30,등급!$A$5:$A$12,0))&"개",INDEX(등급!$I$5:$I$12,MATCH($D30,등급!$A$5:$A$12,0))&"~"&INDEX(등급!$J$5:$J$12,MATCH($D30,등급!$A$5:$A$12,0))&"개")) -> - | N30: =IF(INDEX(등급!$L$5:$L$12,MATCH($D30,등급!$A$5:$A$12,0))=0,"-",INDEX(등급!$K$5:$K$12,MATCH($D30,등급!$A$5:$A$12,0))&"~"&INDEX(등급!$L$5:$L$12,MATCH($D30,등급!$A$5:$A$12,0))&"개") -> -
A31: =장비_기본!B8 -> 성벽 판금갑 | B31: =장비_기본!C8 -> 갑옷 | C31: =장비_기본!D8 -> 탱커 | D31: R | E31: =장비_기본!F8 -> 체력 | F31: =장비_기본!G8*INDEX(등급!$C$5:$C$12,MATCH($D31,등급!$A$5:$A$12,0)) -> 88.4 | G31: =장비_기본!H8 -> 받는 피해 감소 | H31: =장비_기본!I8*INDEX(등급!$C$5:$C$12,MATCH($D31,등급!$A$5:$A$12,0)) -> 0.0102 | I31: =장비_기본!J8 -> 차지 공격 피해 -[값]% | J31: =ROUND(장비_기본!K8*INDEX(등급!$F$5:$F$12,MATCH($D31,등급!$A$5:$A$12,0)),1) -> 9 | K31: =INDEX(등급!$D$5:$D$12,MATCH($D31,등급!$A$5:$A$12,0)) -> 1 | L31: =IF(INDEX(등급!$H$5:$H$12,MATCH($D31,등급!$A$5:$A$12,0))=0,"-",IF(INDEX(등급!$G$5:$G$12,MATCH($D31,등급!$A$5:$A$12,0))=INDEX(등급!$H$5:$H$12,MATCH($D31,등급!$A$5:$A$12,0)),INDEX(등급!$G$5:$G$12,MATCH($D31,등급!$A$5:$A$12,0))&"칸",INDEX(등급!$G$5:$G$12,MATCH($D31,등급!$A$5:$A$12,0))&"~"&INDEX(등급!$H$5:$H$12,MATCH($D31,등급!$A$5:$A$12,0))&"칸")) -> - | M31: =IF(INDEX(등급!$J$5:$J$12,MATCH($D31,등급!$A$5:$A$12,0))=0,"-",IF(INDEX(등급!$I$5:$I$12,MATCH($D31,등급!$A$5:$A$12,0))=INDEX(등급!$J$5:$J$12,MATCH($D31,등급!$A$5:$A$12,0)),INDEX(등급!$I$5:$I$12,MATCH($D31,등급!$A$5:$A$12,0))&"개",INDEX(등급!$I$5:$I$12,MATCH($D31,등급!$A$5:$A$12,0))&"~"&INDEX(등급!$J$5:$J$12,MATCH($D31,등급!$A$5:$A$12,0))&"개")) -> - | N31: =IF(INDEX(등급!$L$5:$L$12,MATCH($D31,등급!$A$5:$A$12,0))=0,"-",INDEX(등급!$K$5:$K$12,MATCH($D31,등급!$A$5:$A$12,0))&"~"&INDEX(등급!$L$5:$L$12,MATCH($D31,등급!$A$5:$A$12,0))&"개") -> -
A32: =장비_기본!B8 -> 성벽 판금갑 | B32: =장비_기본!C8 -> 갑옷 | C32: =장비_기본!D8 -> 탱커 | D32: SR | E32: =장비_기본!F8 -> 체력 | F32: =장비_기본!G8*INDEX(등급!$C$5:$C$12,MATCH($D32,등급!$A$5:$A$12,0)) -> 109.2 | G32: =장비_기본!H8 -> 받는 피해 감소 | H32: =장비_기본!I8*INDEX(등급!$C$5:$C$12,MATCH($D32,등급!$A$5:$A$12,0)) -> 0.0126 | I32: =장비_기본!J8 -> 차지 공격 피해 -[값]% | J32: =ROUND(장비_기본!K8*INDEX(등급!$F$5:$F$12,MATCH($D32,등급!$A$5:$A$12,0)),1) -> 10.5 | K32: =INDEX(등급!$D$5:$D$12,MATCH($D32,등급!$A$5:$A$12,0)) -> 2 | L32: =IF(INDEX(등급!$H$5:$H$12,MATCH($D32,등급!$A$5:$A$12,0))=0,"-",IF(INDEX(등급!$G$5:$G$12,MATCH($D32,등급!$A$5:$A$12,0))=INDEX(등급!$H$5:$H$12,MATCH($D32,등급!$A$5:$A$12,0)),INDEX(등급!$G$5:$G$12,MATCH($D32,등급!$A$5:$A$12,0))&"칸",INDEX(등급!$G$5:$G$12,MATCH($D32,등급!$A$5:$A$12,0))&"~"&INDEX(등급!$H$5:$H$12,MATCH($D32,등급!$A$5:$A$12,0))&"칸")) -> - | M32: =IF(INDEX(등급!$J$5:$J$12,MATCH($D32,등급!$A$5:$A$12,0))=0,"-",IF(INDEX(등급!$I$5:$I$12,MATCH($D32,등급!$A$5:$A$12,0))=INDEX(등급!$J$5:$J$12,MATCH($D32,등급!$A$5:$A$12,0)),INDEX(등급!$I$5:$I$12,MATCH($D32,등급!$A$5:$A$12,0))&"개",INDEX(등급!$I$5:$I$12,MATCH($D32,등급!$A$5:$A$12,0))&"~"&INDEX(등급!$J$5:$J$12,MATCH($D32,등급!$A$5:$A$12,0))&"개")) -> - | N32: =IF(INDEX(등급!$L$5:$L$12,MATCH($D32,등급!$A$5:$A$12,0))=0,"-",INDEX(등급!$K$5:$K$12,MATCH($D32,등급!$A$5:$A$12,0))&"~"&INDEX(등급!$L$5:$L$12,MATCH($D32,등급!$A$5:$A$12,0))&"개") -> -
A33: =장비_기본!B8 -> 성벽 판금갑 | B33: =장비_기본!C8 -> 갑옷 | C33: =장비_기본!D8 -> 탱커 | D33: SSR | E33: =장비_기본!F8 -> 체력 | F33: =장비_기본!G8*INDEX(등급!$C$5:$C$12,MATCH($D33,등급!$A$5:$A$12,0)) -> 132.6 | G33: =장비_기본!H8 -> 받는 피해 감소 | H33: =장비_기본!I8*INDEX(등급!$C$5:$C$12,MATCH($D33,등급!$A$5:$A$12,0)) -> 0.0153 | I33: =장비_기본!J8 -> 차지 공격 피해 -[값]% | J33: =ROUND(장비_기본!K8*INDEX(등급!$F$5:$F$12,MATCH($D33,등급!$A$5:$A$12,0)),1) -> 12 | K33: =INDEX(등급!$D$5:$D$12,MATCH($D33,등급!$A$5:$A$12,0)) -> 3 | L33: =IF(INDEX(등급!$H$5:$H$12,MATCH($D33,등급!$A$5:$A$12,0))=0,"-",IF(INDEX(등급!$G$5:$G$12,MATCH($D33,등급!$A$5:$A$12,0))=INDEX(등급!$H$5:$H$12,MATCH($D33,등급!$A$5:$A$12,0)),INDEX(등급!$G$5:$G$12,MATCH($D33,등급!$A$5:$A$12,0))&"칸",INDEX(등급!$G$5:$G$12,MATCH($D33,등급!$A$5:$A$12,0))&"~"&INDEX(등급!$H$5:$H$12,MATCH($D33,등급!$A$5:$A$12,0))&"칸")) -> - | M33: =IF(INDEX(등급!$J$5:$J$12,MATCH($D33,등급!$A$5:$A$12,0))=0,"-",IF(INDEX(등급!$I$5:$I$12,MATCH($D33,등급!$A$5:$A$12,0))=INDEX(등급!$J$5:$J$12,MATCH($D33,등급!$A$5:$A$12,0)),INDEX(등급!$I$5:$I$12,MATCH($D33,등급!$A$5:$A$12,0))&"개",INDEX(등급!$I$5:$I$12,MATCH($D33,등급!$A$5:$A$12,0))&"~"&INDEX(등급!$J$5:$J$12,MATCH($D33,등급!$A$5:$A$12,0))&"개")) -> - | N33: =IF(INDEX(등급!$L$5:$L$12,MATCH($D33,등급!$A$5:$A$12,0))=0,"-",INDEX(등급!$K$5:$K$12,MATCH($D33,등급!$A$5:$A$12,0))&"~"&INDEX(등급!$L$5:$L$12,MATCH($D33,등급!$A$5:$A$12,0))&"개") -> -
A34: =장비_기본!B8 -> 성벽 판금갑 | B34: =장비_기본!C8 -> 갑옷 | C34: =장비_기본!D8 -> 탱커 | D34: UR | E34: =장비_기본!F8 -> 체력 | F34: =장비_기본!G8*INDEX(등급!$C$5:$C$12,MATCH($D34,등급!$A$5:$A$12,0)) -> 158.6 | G34: =장비_기본!H8 -> 받는 피해 감소 | H34: =장비_기본!I8*INDEX(등급!$C$5:$C$12,MATCH($D34,등급!$A$5:$A$12,0)) -> 0.0183 | I34: =장비_기본!J8 -> 차지 공격 피해 -[값]% | J34: =ROUND(장비_기본!K8*INDEX(등급!$F$5:$F$12,MATCH($D34,등급!$A$5:$A$12,0)),1) -> 13.8 | K34: =INDEX(등급!$D$5:$D$12,MATCH($D34,등급!$A$5:$A$12,0)) -> 4 | L34: =IF(INDEX(등급!$H$5:$H$12,MATCH($D34,등급!$A$5:$A$12,0))=0,"-",IF(INDEX(등급!$G$5:$G$12,MATCH($D34,등급!$A$5:$A$12,0))=INDEX(등급!$H$5:$H$12,MATCH($D34,등급!$A$5:$A$12,0)),INDEX(등급!$G$5:$G$12,MATCH($D34,등급!$A$5:$A$12,0))&"칸",INDEX(등급!$G$5:$G$12,MATCH($D34,등급!$A$5:$A$12,0))&"~"&INDEX(등급!$H$5:$H$12,MATCH($D34,등급!$A$5:$A$12,0))&"칸")) -> - | M34: =IF(INDEX(등급!$J$5:$J$12,MATCH($D34,등급!$A$5:$A$12,0))=0,"-",IF(INDEX(등급!$I$5:$I$12,MATCH($D34,등급!$A$5:$A$12,0))=INDEX(등급!$J$5:$J$12,MATCH($D34,등급!$A$5:$A$12,0)),INDEX(등급!$I$5:$I$12,MATCH($D34,등급!$A$5:$A$12,0))&"개",INDEX(등급!$I$5:$I$12,MATCH($D34,등급!$A$5:$A$12,0))&"~"&INDEX(등급!$J$5:$J$12,MATCH($D34,등급!$A$5:$A$12,0))&"개")) -> - | N34: =IF(INDEX(등급!$L$5:$L$12,MATCH($D34,등급!$A$5:$A$12,0))=0,"-",INDEX(등급!$K$5:$K$12,MATCH($D34,등급!$A$5:$A$12,0))&"~"&INDEX(등급!$L$5:$L$12,MATCH($D34,등급!$A$5:$A$12,0))&"개") -> -
A35: =장비_기본!B8 -> 성벽 판금갑 | B35: =장비_기본!C8 -> 갑옷 | C35: =장비_기본!D8 -> 탱커 | D35: L | E35: =장비_기본!F8 -> 체력 | F35: =장비_기본!G8*INDEX(등급!$C$5:$C$12,MATCH($D35,등급!$A$5:$A$12,0)) -> 166.4 | G35: =장비_기본!H8 -> 받는 피해 감소 | H35: =장비_기본!I8*INDEX(등급!$C$5:$C$12,MATCH($D35,등급!$A$5:$A$12,0)) -> 0.0192 | I35: =장비_기본!J8 -> 차지 공격 피해 -[값]% | J35: =ROUND(장비_기본!K8*INDEX(등급!$F$5:$F$12,MATCH($D35,등급!$A$5:$A$12,0)),1) -> 15.9 | K35: =INDEX(등급!$D$5:$D$12,MATCH($D35,등급!$A$5:$A$12,0)) -> 4 | L35: =IF(INDEX(등급!$H$5:$H$12,MATCH($D35,등급!$A$5:$A$12,0))=0,"-",IF(INDEX(등급!$G$5:$G$12,MATCH($D35,등급!$A$5:$A$12,0))=INDEX(등급!$H$5:$H$12,MATCH($D35,등급!$A$5:$A$12,0)),INDEX(등급!$G$5:$G$12,MATCH($D35,등급!$A$5:$A$12,0))&"칸",INDEX(등급!$G$5:$G$12,MATCH($D35,등급!$A$5:$A$12,0))&"~"&INDEX(등급!$H$5:$H$12,MATCH($D35,등급!$A$5:$A$12,0))&"칸")) -> 1칸 | M35: =IF(INDEX(등급!$J$5:$J$12,MATCH($D35,등급!$A$5:$A$12,0))=0,"-",IF(INDEX(등급!$I$5:$I$12,MATCH($D35,등급!$A$5:$A$12,0))=INDEX(등급!$J$5:$J$12,MATCH($D35,등급!$A$5:$A$12,0)),INDEX(등급!$I$5:$I$12,MATCH($D35,등급!$A$5:$A$12,0))&"개",INDEX(등급!$I$5:$I$12,MATCH($D35,등급!$A$5:$A$12,0))&"~"&INDEX(등급!$J$5:$J$12,MATCH($D35,등급!$A$5:$A$12,0))&"개")) -> 0~1개 | N35: =IF(INDEX(등급!$L$5:$L$12,MATCH($D35,등급!$A$5:$A$12,0))=0,"-",INDEX(등급!$K$5:$K$12,MATCH($D35,등급!$A$5:$A$12,0))&"~"&INDEX(등급!$L$5:$L$12,MATCH($D35,등급!$A$5:$A$12,0))&"개") -> 0~1개
A36: =장비_기본!B8 -> 성벽 판금갑 | B36: =장비_기본!C8 -> 갑옷 | C36: =장비_기본!D8 -> 탱커 | D36: E | E36: =장비_기본!F8 -> 체력 | F36: =장비_기본!G8*INDEX(등급!$C$5:$C$12,MATCH($D36,등급!$A$5:$A$12,0)) -> 171.6 | G36: =장비_기본!H8 -> 받는 피해 감소 | H36: =장비_기본!I8*INDEX(등급!$C$5:$C$12,MATCH($D36,등급!$A$5:$A$12,0)) -> 0.0198 | I36: =장비_기본!J8 -> 차지 공격 피해 -[값]% | J36: =ROUND(장비_기본!K8*INDEX(등급!$F$5:$F$12,MATCH($D36,등급!$A$5:$A$12,0)),1) -> 18 | K36: =INDEX(등급!$D$5:$D$12,MATCH($D36,등급!$A$5:$A$12,0)) -> 4 | L36: =IF(INDEX(등급!$H$5:$H$12,MATCH($D36,등급!$A$5:$A$12,0))=0,"-",IF(INDEX(등급!$G$5:$G$12,MATCH($D36,등급!$A$5:$A$12,0))=INDEX(등급!$H$5:$H$12,MATCH($D36,등급!$A$5:$A$12,0)),INDEX(등급!$G$5:$G$12,MATCH($D36,등급!$A$5:$A$12,0))&"칸",INDEX(등급!$G$5:$G$12,MATCH($D36,등급!$A$5:$A$12,0))&"~"&INDEX(등급!$H$5:$H$12,MATCH($D36,등급!$A$5:$A$12,0))&"칸")) -> 1~3칸 | M36: =IF(INDEX(등급!$J$5:$J$12,MATCH($D36,등급!$A$5:$A$12,0))=0,"-",IF(INDEX(등급!$I$5:$I$12,MATCH($D36,등급!$A$5:$A$12,0))=INDEX(등급!$J$5:$J$12,MATCH($D36,등급!$A$5:$A$12,0)),INDEX(등급!$I$5:$I$12,MATCH($D36,등급!$A$5:$A$12,0))&"개",INDEX(등급!$I$5:$I$12,MATCH($D36,등급!$A$5:$A$12,0))&"~"&INDEX(등급!$J$5:$J$12,MATCH($D36,등급!$A$5:$A$12,0))&"개")) -> 1개 | N36: =IF(INDEX(등급!$L$5:$L$12,MATCH($D36,등급!$A$5:$A$12,0))=0,"-",INDEX(등급!$K$5:$K$12,MATCH($D36,등급!$A$5:$A$12,0))&"~"&INDEX(등급!$L$5:$L$12,MATCH($D36,등급!$A$5:$A$12,0))&"개") -> 0~2개
A37: =장비_기본!B9 -> 맹세의 사슬갑 | B37: =장비_기본!C9 -> 갑옷 | C37: =장비_기본!D9 -> 탱커 | D37: UC | E37: =장비_기본!F9 -> 체력 | F37: =장비_기본!G9*INDEX(등급!$C$5:$C$12,MATCH($D37,등급!$A$5:$A$12,0)) -> 52 | G37: =장비_기본!H9 -> 받는 피해 감소 | H37: =장비_기본!I9*INDEX(등급!$C$5:$C$12,MATCH($D37,등급!$A$5:$A$12,0)) -> 0.006 | I37: =장비_기본!J9 -> ① 도발 지속 +[값]초 | J37: =ROUND(장비_기본!K9*INDEX(등급!$F$5:$F$12,MATCH($D37,등급!$A$5:$A$12,0)),1) -> 0.3 | K37: =INDEX(등급!$D$5:$D$12,MATCH($D37,등급!$A$5:$A$12,0)) -> 0 | L37: =IF(INDEX(등급!$H$5:$H$12,MATCH($D37,등급!$A$5:$A$12,0))=0,"-",IF(INDEX(등급!$G$5:$G$12,MATCH($D37,등급!$A$5:$A$12,0))=INDEX(등급!$H$5:$H$12,MATCH($D37,등급!$A$5:$A$12,0)),INDEX(등급!$G$5:$G$12,MATCH($D37,등급!$A$5:$A$12,0))&"칸",INDEX(등급!$G$5:$G$12,MATCH($D37,등급!$A$5:$A$12,0))&"~"&INDEX(등급!$H$5:$H$12,MATCH($D37,등급!$A$5:$A$12,0))&"칸")) -> - | M37: =IF(INDEX(등급!$J$5:$J$12,MATCH($D37,등급!$A$5:$A$12,0))=0,"-",IF(INDEX(등급!$I$5:$I$12,MATCH($D37,등급!$A$5:$A$12,0))=INDEX(등급!$J$5:$J$12,MATCH($D37,등급!$A$5:$A$12,0)),INDEX(등급!$I$5:$I$12,MATCH($D37,등급!$A$5:$A$12,0))&"개",INDEX(등급!$I$5:$I$12,MATCH($D37,등급!$A$5:$A$12,0))&"~"&INDEX(등급!$J$5:$J$12,MATCH($D37,등급!$A$5:$A$12,0))&"개")) -> - | N37: =IF(INDEX(등급!$L$5:$L$12,MATCH($D37,등급!$A$5:$A$12,0))=0,"-",INDEX(등급!$K$5:$K$12,MATCH($D37,등급!$A$5:$A$12,0))&"~"&INDEX(등급!$L$5:$L$12,MATCH($D37,등급!$A$5:$A$12,0))&"개") -> -
A38: =장비_기본!B9 -> 맹세의 사슬갑 | B38: =장비_기본!C9 -> 갑옷 | C38: =장비_기본!D9 -> 탱커 | D38: C | E38: =장비_기본!F9 -> 체력 | F38: =장비_기본!G9*INDEX(등급!$C$5:$C$12,MATCH($D38,등급!$A$5:$A$12,0)) -> 75.4 | G38: =장비_기본!H9 -> 받는 피해 감소 | H38: =장비_기본!I9*INDEX(등급!$C$5:$C$12,MATCH($D38,등급!$A$5:$A$12,0)) -> 0.0087 | I38: =장비_기본!J9 -> ① 도발 지속 +[값]초 | J38: =ROUND(장비_기본!K9*INDEX(등급!$F$5:$F$12,MATCH($D38,등급!$A$5:$A$12,0)),1) -> 0.4 | K38: =INDEX(등급!$D$5:$D$12,MATCH($D38,등급!$A$5:$A$12,0)) -> 0 | L38: =IF(INDEX(등급!$H$5:$H$12,MATCH($D38,등급!$A$5:$A$12,0))=0,"-",IF(INDEX(등급!$G$5:$G$12,MATCH($D38,등급!$A$5:$A$12,0))=INDEX(등급!$H$5:$H$12,MATCH($D38,등급!$A$5:$A$12,0)),INDEX(등급!$G$5:$G$12,MATCH($D38,등급!$A$5:$A$12,0))&"칸",INDEX(등급!$G$5:$G$12,MATCH($D38,등급!$A$5:$A$12,0))&"~"&INDEX(등급!$H$5:$H$12,MATCH($D38,등급!$A$5:$A$12,0))&"칸")) -> - | M38: =IF(INDEX(등급!$J$5:$J$12,MATCH($D38,등급!$A$5:$A$12,0))=0,"-",IF(INDEX(등급!$I$5:$I$12,MATCH($D38,등급!$A$5:$A$12,0))=INDEX(등급!$J$5:$J$12,MATCH($D38,등급!$A$5:$A$12,0)),INDEX(등급!$I$5:$I$12,MATCH($D38,등급!$A$5:$A$12,0))&"개",INDEX(등급!$I$5:$I$12,MATCH($D38,등급!$A$5:$A$12,0))&"~"&INDEX(등급!$J$5:$J$12,MATCH($D38,등급!$A$5:$A$12,0))&"개")) -> - | N38: =IF(INDEX(등급!$L$5:$L$12,MATCH($D38,등급!$A$5:$A$12,0))=0,"-",INDEX(등급!$K$5:$K$12,MATCH($D38,등급!$A$5:$A$12,0))&"~"&INDEX(등급!$L$5:$L$12,MATCH($D38,등급!$A$5:$A$12,0))&"개") -> -
A39: =장비_기본!B9 -> 맹세의 사슬갑 | B39: =장비_기본!C9 -> 갑옷 | C39: =장비_기본!D9 -> 탱커 | D39: R | E39: =장비_기본!F9 -> 체력 | F39: =장비_기본!G9*INDEX(등급!$C$5:$C$12,MATCH($D39,등급!$A$5:$A$12,0)) -> 88.4 | G39: =장비_기본!H9 -> 받는 피해 감소 | H39: =장비_기본!I9*INDEX(등급!$C$5:$C$12,MATCH($D39,등급!$A$5:$A$12,0)) -> 0.0102 | I39: =장비_기본!J9 -> ① 도발 지속 +[값]초 | J39: =ROUND(장비_기본!K9*INDEX(등급!$F$5:$F$12,MATCH($D39,등급!$A$5:$A$12,0)),1) -> 0.5 | K39: =INDEX(등급!$D$5:$D$12,MATCH($D39,등급!$A$5:$A$12,0)) -> 1 | L39: =IF(INDEX(등급!$H$5:$H$12,MATCH($D39,등급!$A$5:$A$12,0))=0,"-",IF(INDEX(등급!$G$5:$G$12,MATCH($D39,등급!$A$5:$A$12,0))=INDEX(등급!$H$5:$H$12,MATCH($D39,등급!$A$5:$A$12,0)),INDEX(등급!$G$5:$G$12,MATCH($D39,등급!$A$5:$A$12,0))&"칸",INDEX(등급!$G$5:$G$12,MATCH($D39,등급!$A$5:$A$12,0))&"~"&INDEX(등급!$H$5:$H$12,MATCH($D39,등급!$A$5:$A$12,0))&"칸")) -> - | M39: =IF(INDEX(등급!$J$5:$J$12,MATCH($D39,등급!$A$5:$A$12,0))=0,"-",IF(INDEX(등급!$I$5:$I$12,MATCH($D39,등급!$A$5:$A$12,0))=INDEX(등급!$J$5:$J$12,MATCH($D39,등급!$A$5:$A$12,0)),INDEX(등급!$I$5:$I$12,MATCH($D39,등급!$A$5:$A$12,0))&"개",INDEX(등급!$I$5:$I$12,MATCH($D39,등급!$A$5:$A$12,0))&"~"&INDEX(등급!$J$5:$J$12,MATCH($D39,등급!$A$5:$A$12,0))&"개")) -> - | N39: =IF(INDEX(등급!$L$5:$L$12,MATCH($D39,등급!$A$5:$A$12,0))=0,"-",INDEX(등급!$K$5:$K$12,MATCH($D39,등급!$A$5:$A$12,0))&"~"&INDEX(등급!$L$5:$L$12,MATCH($D39,등급!$A$5:$A$12,0))&"개") -> -
A40: =장비_기본!B9 -> 맹세의 사슬갑 | B40: =장비_기본!C9 -> 갑옷 | C40: =장비_기본!D9 -> 탱커 | D40: SR | E40: =장비_기본!F9 -> 체력 | F40: =장비_기본!G9*INDEX(등급!$C$5:$C$12,MATCH($D40,등급!$A$5:$A$12,0)) -> 109.2 | G40: =장비_기본!H9 -> 받는 피해 감소 | H40: =장비_기본!I9*INDEX(등급!$C$5:$C$12,MATCH($D40,등급!$A$5:$A$12,0)) -> 0.0126 | I40: =장비_기본!J9 -> ① 도발 지속 +[값]초 | J40: =ROUND(장비_기본!K9*INDEX(등급!$F$5:$F$12,MATCH($D40,등급!$A$5:$A$12,0)),1) -> 0.5 | K40: =INDEX(등급!$D$5:$D$12,MATCH($D40,등급!$A$5:$A$12,0)) -> 2 | L40: =IF(INDEX(등급!$H$5:$H$12,MATCH($D40,등급!$A$5:$A$12,0))=0,"-",IF(INDEX(등급!$G$5:$G$12,MATCH($D40,등급!$A$5:$A$12,0))=INDEX(등급!$H$5:$H$12,MATCH($D40,등급!$A$5:$A$12,0)),INDEX(등급!$G$5:$G$12,MATCH($D40,등급!$A$5:$A$12,0))&"칸",INDEX(등급!$G$5:$G$12,MATCH($D40,등급!$A$5:$A$12,0))&"~"&INDEX(등급!$H$5:$H$12,MATCH($D40,등급!$A$5:$A$12,0))&"칸")) -> - | M40: =IF(INDEX(등급!$J$5:$J$12,MATCH($D40,등급!$A$5:$A$12,0))=0,"-",IF(INDEX(등급!$I$5:$I$12,MATCH($D40,등급!$A$5:$A$12,0))=INDEX(등급!$J$5:$J$12,MATCH($D40,등급!$A$5:$A$12,0)),INDEX(등급!$I$5:$I$12,MATCH($D40,등급!$A$5:$A$12,0))&"개",INDEX(등급!$I$5:$I$12,MATCH($D40,등급!$A$5:$A$12,0))&"~"&INDEX(등급!$J$5:$J$12,MATCH($D40,등급!$A$5:$A$12,0))&"개")) -> - | N40: =IF(INDEX(등급!$L$5:$L$12,MATCH($D40,등급!$A$5:$A$12,0))=0,"-",INDEX(등급!$K$5:$K$12,MATCH($D40,등급!$A$5:$A$12,0))&"~"&INDEX(등급!$L$5:$L$12,MATCH($D40,등급!$A$5:$A$12,0))&"개") -> -
